Workbook

Sheet T4.x - MUX
A1: Teensy4 | B1: T4.1 | C1: MMOD | D1: Name | E1: ALT0 | F1: ALt1 | G1: ALT2 | H1: ALT3 | I1: ALT4 | J1: Alt5 | K1: ALT6 | L1: ALT7 | M1: ALT8 | N1: ALT9
A2: =_xlfn.XLOOKUP(D2,'T4'!$B$2:$B$56,'T4'!$A$2:$A$56,"") -> 1 | B2: =_xlfn.XLOOKUP(D2,'T4.1 MUX'!$B$2:$B$56,'T4.1 MUX'!$A$2:$A$56,"") -> 1 | C2: =_xlfn.XLOOKUP(D2, Micromod!$D$2:$D$47,Micromod!$A$2:$A$47,"") -> 01 | D2: AD_B0_02 | E2: FLEXCAN2_TX | F2: XBAR1_INOUT16 | G2: LPUART6_TX | H2: USB_OTG1_PWR | I2: LEXPWM1_PWMX0 | J2: GPIO1_IO02 | K2: LPI2C1_HREQ | L2: LPSPI3_SDI
A3: =_xlfn.XLOOKUP(D3,'T4'!$B$2:$B$56,'T4'!$A$2:$A$56,"") -> 0 | B3: =_xlfn.XLOOKUP(D3,'T4.1 MUX'!$B$2:$B$56,'T4.1 MUX'!$A$2:$A$56,"") -> 0 | C3: =_xlfn.XLOOKUP(D3, Micromod!$D$2:$D$47,Micromod!$A$2:$A$47,"") -> 00 | D3: AD_B0_03 | E3: FLEXCAN2_RX | F3: XBAR1_INOUT17 | G3: LPUART6_RX | H3: USB_OTG1_OC | I3: FLEXPWM1_PWMX01 | J3: GPIO1_IO03 | K3: REF_CLK_24M | L3: LPSPI3_PCS0
A4: =_xlfn.XLOOKUP(D4,'T4'!$B$2:$B$56,'T4'!$A$2:$A$56,"") -> 24/A10 | B4: =_xlfn.XLOOKUP(D4,'T4.1 MUX'!$B$2:$B$56,'T4.1 MUX'!$A$2:$A$56,"") -> 24/A10 | C4: =_xlfn.XLOOKUP(D4, Micromod!$D$2:$D$47,Micromod!$A$2:$A$47,"") -> 24/A10 | D4: AD_B0_12 | E4: LPI2C4_SCL | F4: CCM_PMIC_READY | G4: LPUART1_TX | H4: WDOG2_WDOG_B | I4: FLEXPWM1_PWMX02 | J4: GPIO1_IO12 | K4: ENET_1588_EVENT1_OUT | L4: NMI_GLUE_NMI
A5: =_xlfn.XLOOKUP(D5,'T4'!$B$2:$B$56,'T4'!$A$2:$A$56,"") -> 25/A11 | B5: =_xlfn.XLOOKUP(D5,'T4.1 MUX'!$B$2:$B$56,'T4.1 MUX'!$A$2:$A$56,"") -> 25/A11 | C5: =_xlfn.XLOOKUP(D5, Micromod!$D$2:$D$47,Micromod!$A$2:$A$47,"") -> 25/A11 | D5: AD_B0_13 | E5: LPI2C4_SDA | F5: GPT1_CLK | G5: LPUART1_RX | H5: EWM_OUT_B | I5: FLEXPWM1_PWMX03 | J5: GPIO1_IO13 | K5: ENET_1588_EVENT1_IN | L5: REF_CLK_24M
A6: =_xlfn.XLOOKUP(D6,'T4'!$B$2:$B$56,'T4'!$A$2:$A$56,"") -> 19/A5 | B6: =_xlfn.XLOOKUP(D6,'T4.1 MUX'!$B$2:$B$56,'T4.1 MUX'!$A$2:$A$56,"") -> 19/A5 | C6: =_xlfn.XLOOKUP(D6, Micromod!$D$2:$D$47,Micromod!$A$2:$A$47,"") -> 19/A5 | D6: AD_B1_00 | E6: USB_OTG2_ID | F6: QTIMER3_TIMER0 | G6: LPUART2_CTS_B | H6: LPI2C1_SCL | I6: WDOG1_B | J6: GPIO1_IO16 | K6: USDHC1_W | L6: KPP_ROW07 | M6: ENET2_1588_EVENT0_OUT | N6: FLEXIO3_FLEXIO00
A7: =_xlfn.XLOOKUP(D7,'T4'!$B$2:$B$56,'T4'!$A$2:$A$56,"") -> 18/A4 | B7: =_xlfn.XLOOKUP(D7,'T4.1 MUX'!$B$2:$B$56,'T4.1 MUX'!$A$2:$A$56,"") -> 18/A4 | C7: =_xlfn.XLOOKUP(D7, Micromod!$D$2:$D$47,Micromod!$A$2:$A$47,"") -> 18/A4 | D7: AD_B1_01 | E7: USB_OTG1_PWR | F7: QTIMER3_TIMER1 | G7: LPUART2_RTS_B | H7: LPI2C1_SDA | I7: CCM_PMIC_READY | J7: GPIO1_IO17 | K7: USDHC1_VSELECT | L7: KPP_COL07 | M7: ENET2_1588_EVENT0_IN | N7: FLEXIO3_FLEXIO01
A8: =_xlfn.XLOOKUP(D8,'T4'!$B$2:$B$56,'T4'!$A$2:$A$56,"") -> 14/A0 | B8: =_xlfn.XLOOKUP(D8,'T4.1 MUX'!$B$2:$B$56,'T4.1 MUX'!$A$2:$A$56,"") -> 14/A0 | C8: =_xlfn.XLOOKUP(D8, Micromod!$D$2:$D$47,Micromod!$A$2:$A$47,"") -> 14/A0 | D8: AD_B1_02 | E8: USB_OTG1_ID | F8: QTIMER3_TIMER2 | G8: LPUART2_TX | H8: SPDIF_OUT | I8: ENET_1588_EVENT2_OUT | J8: GPIO1_IO18 | K8: USDHC1_CD_B | L8: KPP_ROW06 | M8: GPT2_CLK | N8: FLEXIO3_FLEXIO02
A9: =_xlfn.XLOOKUP(D9,'T4'!$B$2:$B$56,'T4'!$A$2:$A$56,"") -> 15/A1 | B9: =_xlfn.XLOOKUP(D9,'T4.1 MUX'!$B$2:$B$56,'T4.1 MUX'!$A$2:$A$56,"") -> 15/A1 | C9: =_xlfn.XLOOKUP(D9, Micromod!$D$2:$D$47,Micromod!$A$2:$A$47,"") -> 15/A1 | D9: AD_B1_03 | E9: USB_OTG1_OC | F9: QTIMER3_TIMER3 | G9: LPUART2_RX | H9: SPDIF_IN | I9: ENET_1588_EVENT2_IN | J9: GPIO1_IO19 | K9: USDHC2_CD_B | L9: KPP_COL06 | M9: GPT2_CAPTURE1 | N9: FLEXIO3_FLEXIO03
A10: =_xlfn.XLOOKUP(D10,'T4'!$B$2:$B$56,'T4'!$A$2:$A$56,"") | B10: =_xlfn.XLOOKUP(D10,'T4.1 MUX'!$B$2:$B$56,'T4.1 MUX'!$A$2:$A$56,"") -> 40/A16 | C10: =_xlfn.XLOOKUP(D10, Micromod!$D$2:$D$47,Micromod!$A$2:$A$47,"") | D10: AD_B1_04 | E10: FLEXSPIB_DATA03 | F10: ENET_MDC | G10: LPUART3_CTS_B | H10: SPDIF_SR_CLK | I10: CSI_PIXCLK | J10: GPIO1_IO20 | K10: USDHC2_DATA0 | L10: KPP_ROW05 | M10: GPT2_CAPTURE2 | N10: FLEXIO3_FLEXIO04
A11: =_xlfn.XLOOKUP(D11,'T4'!$B$2:$B$56,'T4'!$A$2:$A$56,"") | B11: =_xlfn.XLOOKUP(D11,'T4.1 MUX'!$B$2:$B$56,'T4.1 MUX'!$A$2:$A$56,"") -> 41/A17 | C11: =_xlfn.XLOOKUP(D11, Micromod!$D$2:$D$47,Micromod!$A$2:$A$47,"") | D11: AD_B1_05 | E11: FLEXSPIB_DATA02 | F11: ENET_MDIO | G11: LPUART3_RTS_B | H11: SPDIF_OUT | I11: CSI_MCLK | J11: GPIO1_IO21 | K11: USDHC2_DATA1 | L11: KPP_COL05 | M11: GPT2_COMPARE1 | N11: FLEXIO3_FLEXIO05
A12: =_xlfn.XLOOKUP(D12,'T4'!$B$2:$B$56,'T4'!$A$2:$A$56,"") -> 17/A3 | B12: =_xlfn.XLOOKUP(D12,'T4.1 MUX'!$B$2:$B$56,'T4.1 MUX'!$A$2:$A$56,"") -> 17/A3 | C12: =_xlfn.XLOOKUP(D12, Micromod!$D$2:$D$47,Micromod!$A$2:$A$47,"") -> 17/A3 | D12: AD_B1_06 | E12: FLEXSPIB_DATA01 | F12: LPI2C3_SDA | G12: LPUART3_TX | H12: SPDIF_LOCK | I12: CSI_VSYNC | J12: GPIO1_IO22 | K12: USDHC2_DATA2 | L12: KPP_ROW04 | M12: GPT2_COMPARE2 | N12: FLEXIO3_FLEXIO06
A13: =_xlfn.XLOOKUP(D13,'T4'!$B$2:$B$56,'T4'!$A$2:$A$56,"") -> 16/A2 | B13: =_xlfn.XLOOKUP(D13,'T4.1 MUX'!$B$2:$B$56,'T4.1 MUX'!$A$2:$A$56,"") -> 16/A2 | C13: =_xlfn.XLOOKUP(D13, Micromod!$D$2:$D$47,Micromod!$A$2:$A$47,"") -> 16/A2 | D13: AD_B1_07 | E13: FLEXSPIB_DATA00 | F13: LPI2C3_SCL | G13: LPUART3_RX | H13: SPDIF_EXT_CLK | I13: CSI_HSYNC | J13: GPIO1_IO23 | K13: USDHC2_DATA3 | L13: KPP_COL04 | M13: GPT2_COMPARE3 | N13: FLEXIO3_FLEXIO07
A14: =_xlfn.XLOOKUP(D14,'T4'!$B$2:$B$56,'T4'!$A$2:$A$56,"") -> 22/A8 | B14: =_xlfn.XLOOKUP(D14,'T4.1 MUX'!$B$2:$B$56,'T4.1 MUX'!$A$2:$A$56,"") -> 22/A8 | C14: =_xlfn.XLOOKUP(D14, Micromod!$D$2:$D$47,Micromod!$A$2:$A$47,"") -> 22/A8 | D14: AD_B1_08 | E14: FLEXSPIA_SS1_B | F14: FLEXPWM4_PWMA00 | G14: FLEXCAN1_TX | H14: CCM_PMIC_READY | I14: CSI_DATA09 | J14: GPIO1_IO24 | K14: USDHC2_CMD | L14: KPP_ROW03 | N14: FLEXIO3_FLEXIO08
A15: =_xlfn.XLOOKUP(D15,'T4'!$B$2:$B$56,'T4'!$A$2:$A$56,"") -> 23/A9 | B15: =_xlfn.XLOOKUP(D15,'T4.1 MUX'!$B$2:$B$56,'T4.1 MUX'!$A$2:$A$56,"") -> 23/A9 | C15: =_xlfn.XLOOKUP(D15, Micromod!$D$2:$D$47,Micromod!$A$2:$A$47,"") -> 23/A9 | D15: AD_B1_09 | E15: FLEXSPIA_DQS | F15: FLEXPWM4_PWMA01 | G15: FLEXCAN1_RX | H15: SAI1_MCLK | I15: CSI_DATA08 | J15: GPIO1_IO25 | K15: USDHC2_CLK | L15: KPP_COL03 | N15: FLEXIO3_FLEXIO09
A16: =_xlfn.XLOOKUP(D16,'T4'!$B$2:$B$56,'T4'!$A$2:$A$56,"") -> 20/A6 | B16: =_xlfn.XLOOKUP(D16,'T4.1 MUX'!$B$2:$B$56,'T4.1 MUX'!$A$2:$A$56,"") -> 20/A6 | C16: =_xlfn.XLOOKUP(D16, Micromod!$D$2:$D$47,Micromod!$A$2:$A$47,"") -> 20/A6 | D16: AD_B1_10 | E16: FLEXSPIA_DATA03 | F16: WDOG1_B | G16: LPUART8_TX | H16: SAI1_RX_SYNC | I16: CSI_DATA07 | J16: GPIO1_IO26 | K16: USDHC2_WP | L16: KPP_ROW02 | M16: ENET2_1588_EVENT1_OUT | N16: FLEXIO3_FLEXIO10
A17: =_xlfn.XLOOKUP(D17,'T4'!$B$2:$B$56,'T4'!$A$2:$A$56,"") -> 21/A7 | B17: =_xlfn.XLOOKUP(D17,'T4.1 MUX'!$B$2:$B$56,'T4.1 MUX'!$A$2:$A$56,"") -> 21/A7 | C17: =_xlfn.XLOOKUP(D17, Micromod!$D$2:$D$47,Micromod!$A$2:$A$47,"") -> 21/A7 | D17: AD_B1_11 | E17: FLEXSPIA_DATA02 | F17: EWM_OUT_B | G17: LPUART8_RX | H17: SAI1_RX_BCL | I17: CSI_DATA06 | J17: GPIO1_IO27 | K17: USDHC2_RESET_B | L17: KPP_COL02 | M17: ENET2_1588_EVENT1_IN | N17: FLEXIO3_FLEXIO11
A18: =_xlfn.XLOOKUP(D18,'T4'!$B$2:$B$56,'T4'!$A$2:$A$56,"") | B18: =_xlfn.XLOOKUP(D18,'T4.1 MUX'!$B$2:$B$56,'T4.1 MUX'!$A$2:$A$56,"") -> 38/A14 | C18: =_xlfn.XLOOKUP(D18, Micromod!$D$2:$D$47,Micromod!$A$2:$A$47,"") | D18: AD_B1_12 | E18: FLEXSPIA_DATA01 | F18: ACMP_OUT00 | G18: LPSPI3_PCS0 | H18: SAI1_RX_DATA00 | I18: CSI_DATA05 | J18: GPIO1_IO28 | K18: USDHC2_DATA4 | L18: KPP_ROW01 | M18: ENET2_1588_EVENT2_OUT | N18: FLEXIO3_FLEXIO12
A19: =_xlfn.XLOOKUP(D19,'T4'!$B$2:$B$56,'T4'!$A$2:$A$56,"") | B19: =_xlfn.XLOOKUP(D19,'T4.1 MUX'!$B$2:$B$56,'T4.1 MUX'!$A$2:$A$56,"") -> 39/A5 | C19: =_xlfn.XLOOKUP(D19, Micromod!$D$2:$D$47,Micromod!$A$2:$A$47,"") | D19: AD_B1_13 | E19: FLEXSPIA_DATA00 | F19: ACMP_OUT01 | G19: LPSPI3_SDI | H19: SAI1_TX_DATA00 | I19: CSI_DATA04 | J19: GPIO1_IO29 | K19: USDHC2_DATA5 | L19: KPP_COL01 | M19: ENET2_1588_EVENT2_IN | N19: FLEXIO3_FLEXIO13
A20: =_xlfn.XLOOKUP(D20,'T4'!$B$2:$B$56,'T4'!$A$2:$A$56,"") -> 26/A12 | B20: =_xlfn.XLOOKUP(D20,'T4.1 MUX'!$B$2:$B$56,'T4.1 MUX'!$A$2:$A$56,"") -> 26/A12 | C20: =_xlfn.XLOOKUP(D20, Micromod!$D$2:$D$47,Micromod!$A$2:$A$47,"") -> 26/A12 | D20: AD_B1_14 | E20: FLEXSPIA_SCLK | F20: ACMP_OUT02 | G20: LPSPI3_SDO | H20: SAI1_TX_BCLK | I20: CSI_DATA03 | J20: GPIO1_IO30 | K20: USDHC2_DATA6 | L20: KPP_ROW00 | M20: ENET2_1588_EVENT3_OUT | N20: FLEXIO3_FLEXIO14
A21: =_xlfn.XLOOKUP(D21,'T4'!$B$2:$B$56,'T4'!$A$2:$A$56,"") -> 27/A13 | B21: =_xlfn.XLOOKUP(D21,'T4.1 MUX'!$B$2:$B$56,'T4.1 MUX'!$A$2:$A$56,"") -> 27/A13 | C21: =_xlfn.XLOOKUP(D21, Micromod!$D$2:$D$47,Micromod!$A$2:$A$47,"") -> 27/A13 | D21: AD_B1_15 | E21: FLEXSPIA_SS0_B | F21: ACMP_OUT03 | G21: LPSPI3_SCK | H21: SAI1_TX_SYNC | I21: CSI_DATA02 | J21: GPIO1_IO31 | K21: USDHC2_DATA7 | L21: KPP_COL00 | M21: ENET2_1588_EVENT3_IN | N21: FLEXIO3_FLEXIO15
A22: =_xlfn.XLOOKUP(D22,'T4'!$B$2:$B$56,'T4'!$A$2:$A$56,"") -> 10 | B22: =_xlfn.XLOOKUP(D22,'T4.1 MUX'!$B$2:$B$56,'T4.1 MUX'!$A$2:$A$56,"") -> 10 | C22: =_xlfn.XLOOKUP(D22, Micromod!$D$2:$D$47,Micromod!$A$2:$A$47,"") -> 10 | D22: B0_00 | E22: LCD_CLK | F22: QTIMER1_TIMER0 | G22: MQS_RIGHT | H22: LPSPI4_PCS0 | I22: FLEXIO2_FLEXIO00 | J22: GPIO2_IO00 | K22: SEMC_CSX01 | M22: ENET2_MDC
A23: =_xlfn.XLOOKUP(D23,'T4'!$B$2:$B$56,'T4'!$A$2:$A$56,"") -> 12 | B23: =_xlfn.XLOOKUP(D23,'T4.1 MUX'!$B$2:$B$56,'T4.1 MUX'!$A$2:$A$56,"") -> 12 | C23: =_xlfn.XLOOKUP(D23, Micromod!$D$2:$D$47,Micromod!$A$2:$A$47,"") -> 12 | D23: B0_01 | E23: LCD_ENABLE | F23: QTIMER1_TIMER1 | G23: MQS_LEFT | H23: LPSPI4_SDI | I23: FLEXIO2_FLEXIO01 | J23: GPIO2_IO01 | K23: SEMC_CSX02 | M23: ENET2_MDIO
A24: =_xlfn.XLOOKUP(D24,'T4'!$B$2:$B$56,'T4'!$A$2:$A$56,"") -> 11 | B24: =_xlfn.XLOOKUP(D24,'T4.1 MUX'!$B$2:$B$56,'T4.1 MUX'!$A$2:$A$56,"") -> 11 | C24: =_xlfn.XLOOKUP(D24, Micromod!$D$2:$D$47,Micromod!$A$2:$A$47,"") -> 11 | D24: B0_02 | E24: LCD_HSYNC | F24: QTIMER1_TIMER2 | G24: FLEXCAN1_TX | H24: LPSPI4_SDO | I24: FLEXIO2_FLEXIO02 | J24: GPIO2_IO02 | K24: SEMC_CSX03 | M24: ENET2_1588_EVENT0_OUT
A25: =_xlfn.XLOOKUP(D25,'T4'!$B$2:$B$56,'T4'!$A$2:$A$56,"") -> 13 | B25: =_xlfn.XLOOKUP(D25,'T4.1 MUX'!$B$2:$B$56,'T4.1 MUX'!$A$2:$A$56,"") -> 13 | C25: =_xlfn.XLOOKUP(D25, Micromod!$D$2:$D$47,Micromod!$A$2:$A$47,"") -> 13 | D25: B0_03 | E25: LCD_VSYNC | F25: QTIMER2_TIMER0 | G25: FLEXCAN1_RX | H25: LPSPI4_SCK | I25: FLEXIO2_FLEXIO03 | J25: GPIO2_IO03 | K25: WDOG2_RESET_B_DEB | M25: ENET2_1588_EVENT0_IN
A26: =_xlfn.XLOOKUP(D26,'T4'!$B$2:$B$56,'T4'!$A$2:$A$56,"") | B26: =_xlfn.XLOOKUP(D26,'T4.1 MUX'!$B$2:$B$56,'T4.1 MUX'!$A$2:$A$56,"") | C26: =_xlfn.XLOOKUP(D26, Micromod!$D$2:$D$47,Micromod!$A$2:$A$47,"") -> 40 | D26: B0_04 | E26: LCD_DATA00 | F26: QTIMER2_TIMER1 | G26: LPI2C2_SCL | H26: ARM_TRACE0 | I26: FLEXIO2_FLEXIO04 | J26: GPIO2_IO04 | K26: SRC_BOOT_CFG00 | M26: ENET2_TDATA03
A27: =_xlfn.XLOOKUP(D27,'T4'!$B$2:$B$56,'T4'!$A$2:$A$56,"") | B27: =_xlfn.XLOOKUP(D27,'T4.1 MUX'!$B$2:$B$56,'T4.1 MUX'!$A$2:$A$56,"") | C27: =_xlfn.XLOOKUP(D27, Micromod!$D$2:$D$47,Micromod!$A$2:$A$47,"") -> 41 | D27: B0_05 | E27: LCD_DATA01 | F27: QTIMER2_TIMER2 | G27: LPI2C2_SDA | H27: ARM_TRACE1 | I27: FLEXIO2_FLEXIO05 | J27: GPIO2_IO05 | K27: SRC_BOOT_CFG01 | M27: ENET2_TDATA02
A28: =_xlfn.XLOOKUP(D28,'T4'!$B$2:$B$56,'T4'!$A$2:$A$56,"") | B28: =_xlfn.XLOOKUP(D28,'T4.1 MUX'!$B$2:$B$56,'T4.1 MUX'!$A$2:$A$56,"") | C28: =_xlfn.XLOOKUP(D28, Micromod!$D$2:$D$47,Micromod!$A$2:$A$47,"") -> 42 | D28: B0_06 | E28: LCD_DATA02 | F28: QTIMER3_TIMER0 | G28: FLEXPWM2_PWMA00 | H28: ARM_TRACE2 | I28: FLEXIO2_FLEXIO06 | J28: GPIO2_IO06 | K28: SRC_BOOT_CFG02 | M28: ENET2_RX_CLK
A29: =_xlfn.XLOOKUP(D29,'T4'!$B$2:$B$56,'T4'!$A$2:$A$56,"") | B29: =_xlfn.XLOOKUP(D29,'T4.1 MUX'!$B$2:$B$56,'T4.1 MUX'!$A$2:$A$56,"") | C29: =_xlfn.XLOOKUP(D29, Micromod!$D$2:$D$47,Micromod!$A$2:$A$47,"") -> 43 | D29: B0_07 | E29: LCD_DATA03 | F29: QTIMER3_TIMER1 | G29: FLEXPWM2_PWNB00 | H29: ARM_TRACE3 | I29: FLEXIO2_FLEXIO07 | J29: GPIO2_IO07 | K29: SRC_BOOT_CFG03 | M29: ENET2_TX_ER
A30: =_xlfn.XLOOKUP(D30,'T4'!$B$2:$B$56,'T4'!$A$2:$A$56,"") | B30: =_xlfn.XLOOKUP(D30,'T4.1 MUX'!$B$2:$B$56,'T4.1 MUX'!$A$2:$A$56,"") | C30: =_xlfn.XLOOKUP(D30, Micromod!$D$2:$D$47,Micromod!$A$2:$A$47,"") -> 44 | D30: B0_08 | E30: LCD_DATA04 | F30: QTIMER3_TIMER2 | G30: FLEXPWM2_PWMA01 | H30: LPUART3_TX | I30: FLEXIO2_FLEXIO08 | J30: GPIO2_IO08 | K30: SRC_BOOT_CFG04 | M30: ENET2_RDATA03
A31: =_xlfn.XLOOKUP(D31,'T4'!$B$2:$B$56,'T4'!$A$2:$A$56,"") | B31: =_xlfn.XLOOKUP(D31,'T4.1 MUX'!$B$2:$B$56,'T4.1 MUX'!$A$2:$A$56,"") | C31: =_xlfn.XLOOKUP(D31, Micromod!$D$2:$D$47,Micromod!$A$2:$A$47,"") -> 45 | D31: B0_09 | E31: LCD_DATA05 | F31: QTIMER4_TIMER0 | G31: FLEXPWM2_PWMB01 | H31: LPUART3_RX | I31: FLEXIO2_FLEXIO09 | J31: GPIO2_IO09 | K31: SRC_BOOT_CFG05 | M31: ENET2_RDATA02
A32: =_xlfn.XLOOKUP(D32,'T4'!$B$2:$B$56,'T4'!$A$2:$A$56,"") -> 6 | B32: =_xlfn.XLOOKUP(D32,'T4.1 MUX'!$B$2:$B$56,'T4.1 MUX'!$A$2:$A$56,"") -> 6 | C32: =_xlfn.XLOOKUP(D32, Micromod!$D$2:$D$47,Micromod!$A$2:$A$47,"") -> 06 | D32: B0_10 | E32: LCD_DATA06 | F32: QTIMER4_TIMER1 | G32: FLEXPWM2_PWMA02 | H32: SAI1_TX_DATA03 | I32: FLEXIO2_FLEXIO10 | J32: GPIO2_IO10 | K32: SRC_BOOT_CFG06 | M32: ENET2_CRS
A33: =_xlfn.XLOOKUP(D33,'T4'!$B$2:$B$56,'T4'!$A$2:$A$56,"") -> 9 | B33: =_xlfn.XLOOKUP(D33,'T4.1 MUX'!$B$2:$B$56,'T4.1 MUX'!$A$2:$A$56,"") -> 9 | C33: =_xlfn.XLOOKUP(D33, Micromod!$D$2:$D$47,Micromod!$A$2:$A$47,"") -> 09 | D33: B0_11 | E33: LCD_DATA07 | F33: QTIMER4_TIMER2 | G33: FLEXPWM2_PWMB02 | H33: SAI1_TX_DATA02 | I33: FLEXIO2_FLEXIO11 | J33: GPIO2_IO11 | K33: SRC_BOOT_CFG07 | M33: ENET2_COL
A34: =_xlfn.XLOOKUP(D34,'T4'!$B$2:$B$56,'T4'!$A$2:$A$56,"") -> 32 | B34: =_xlfn.XLOOKUP(D34,'T4.1 MUX'!$B$2:$B$56,'T4.1 MUX'!$A$2:$A$56,"") -> 32 | C34: =_xlfn.XLOOKUP(D34, Micromod!$D$2:$D$47,Micromod!$A$2:$A$47,"") -> 32 | D34: B0_12 | E34: LCD_DATA08 | F34: XBAR1_INOUT10 | G34: ARM_TRACE_CLK | H34: SAI1_TX_DATA01 | I34: FLEXIO2_FLEXIO12 | J34: GPIO2_IO12 | K34: SRC_BOOT_CFG08 | M34: ENET2_TDATA00
A35: =_xlfn.XLOOKUP(D35,'T4'!$B$2:$B$56,'T4'!$A$2:$A$56,"") -> 8 | B35: =_xlfn.XLOOKUP(D35,'T4.1 MUX'!$B$2:$B$56,'T4.1 MUX'!$A$2:$A$56,"") -> 8 | C35: =_xlfn.XLOOKUP(D35, Micromod!$D$2:$D$47,Micromod!$A$2:$A$47,"") -> 08 | D35: B1_00 | E35: LCD_DATA12 | F35: XBAR1_INOUT14 | G35: LPUART4_TX | H35: SAI1_RX_DATA00 | I35: FLEXIO2_FLEXIO16 | J35: GPIO2_IO16 | K35: FLEXPWM1_PWMA03 | M35: ENET2_RX_ER | N35: FLEXIO3_FLEXIO16
A36: =_xlfn.XLOOKUP(D36,'T4'!$B$2:$B$56,'T4'!$A$2:$A$56,"") -> 7 | B36: =_xlfn.XLOOKUP(D36,'T4.1 MUX'!$B$2:$B$56,'T4.1 MUX'!$A$2:$A$56,"") -> 7 | C36: =_xlfn.XLOOKUP(D36, Micromod!$D$2:$D$47,Micromod!$A$2:$A$47,"") -> 07 | D36: B1_01 | E36: LCD_DATA13 | F36: XBAR1_INOUT15 | G36: LPUART4_RX | H36: SAI1_TX_DATA00 | I36: FLEXIO2_FLEXIO17 | J36: GPIO2_IO17 | K36: FLEXPWM1_PWMB03 | M36: ENET2_RDATA00 | N36: FLEXIO3_FLEXIO17
A37: =_xlfn.XLOOKUP(D37,'T4'!$B$2:$B$56,'T4'!$A$2:$A$56,"") | B37: =_xlfn.XLOOKUP(D37,'T4.1 MUX'!$B$2:$B$56,'T4.1 MUX'!$A$2:$A$56,"") -> 36 | C37: =_xlfn.XLOOKUP(D37, Micromod!$D$2:$D$47,Micromod!$A$2:$A$47,"") | D37: B1_02 | E37: LCD_DATA14 | F37: XBAR1_INOUT16 | G37: LPSPI4_PCS2 | H37: SAI1_TX_BCLK | I37: FLEXIO2_FLEXIO18 | J37: GPIO2_IO18 | K37: FLEXPWM2_PWMA03 | M37: ENET2_RDATA01 | N37: FLEXIO3_FLEXIO18
A38: =_xlfn.XLOOKUP(D38,'T4'!$B$2:$B$56,'T4'!$A$2:$A$56,"") | B38: =_xlfn.XLOOKUP(D38,'T4.1 MUX'!$B$2:$B$56,'T4.1 MUX'!$A$2:$A$56,"") -> 37 | C38: =_xlfn.XLOOKUP(D38, Micromod!$D$2:$D$47,Micromod!$A$2:$A$47,"") | D38: B1_03 | E38: LCD_DATA15 | F38: XBAR1_INOUT17 | G38: LPSPI4_PCS1 | H38: SAI1_TX_SYNC | I38: FLEXIO2_FLEXIO19 | J38: GPIO2_IO19 | K38: FLEXPWM2_PWMB03 | M38: ENET2_RX_EN | N38: FLEXIO3_FLEXIO19
A39: =_xlfn.XLOOKUP(D39,'T4'!$B$2:$B$56,'T4'!$A$2:$A$56,"") | B39: =_xlfn.XLOOKUP(D39,'T4.1 MUX'!$B$2:$B$56,'T4.1 MUX'!$A$2:$A$56,"") -> 35 | C39: =_xlfn.XLOOKUP(D39, Micromod!$D$2:$D$47,Micromod!$A$2:$A$47,"") | D39: B1_12 | F39: LPUART5_TX | G39: CSI_PIXCLK | H39: ENET_1588_EVENT0_IN | I39: FLEXIO2_FLEXIO28 | J39: GPIO2_IO28 | K39: USDHC1_CD_B | N39: FLEXIO3_FLEXIO28
A40: =_xlfn.XLOOKUP(D40,'T4'!$B$2:$B$56,'T4'!$A$2:$A$56,"") | B40: =_xlfn.XLOOKUP(D40,'T4.1 MUX'!$B$2:$B$56,'T4.1 MUX'!$A$2:$A$56,"") -> 34 | C40: =_xlfn.XLOOKUP(D40, Micromod!$D$2:$D$47,Micromod!$A$2:$A$47,"") | D40: B1_13 | E40: WDOG1_B | F40: LPUART5_RX | G40: CSI_VSYNC | H40: ENET_1588_EVENT0_OUT | I40: FLEXIO2_FLEXIO29 | J40: GPIO2_IO29 | K40: USDHC1_WP | M40: SEMC_DQS4 | N40: FLEXIO3_FLEXIO29
...

Sheet T4
A1: Pin | B1: Name | C1: GPIO | D1: Serial | E1: I2C | F1: SPI | G1: PWM | H1: CAN | I1: Audio | J1: XBAR | K1: FlexIO | L1: Analog | M1: SD
A2: 0 | B2: AD_B0_03 | C2: 1.3 | D2: Serial1(6) RX | F2: SPI1(3) CS0 | G2: PWM1_X1 | H2: 2_RX | J2: IO-17
A3: 1 | B3: AD_B0_02 | C3: 1.2 | D3: Serial1(6) TX | F3: SPI1(3) MISO | G3: PWM1_X0 | H3: 2_TX | J3: IO-16
A4: 2 | B4: EMC_04 | C4: 4.4 | G4: PWM4_A2 | I4: 2:TX_DATA | J4: IO-06 | K4: 1:4
A5: 3 | B5: EMC_05 | C5: 4.5 | G5: PWM4_B2 | I5: 2:TX_SYNC | J5: IO-07 | K5: 1:5
A6: 4 | B6: EMC_06 | C6: 4.6 | G6: PWM2_A0 | I6: 2:TX_BCLK | J6: IO-08 | K6: 1:6
A7: 5 | B7: EMC_08 | C7: 4.8 | G7: PWM2_A1 | I7: 2:RX_DATA | J7: IO-17 | K7: 1:8
A8: 6 | B8: B0_10 | C8: 2.10 | G8: PWM2_A2, QT4_1 | I8: 1:TX3_RX1 | K8: 2:10
A9: 7 | B9: B1_01 | C9: 2.17 | D9: Serial2(4) RX | G9: PWM1_B3 | I9: 1:TX_DATA | J9: IO-15 | K9: 2:17, 3:17
A10: 8 | B10: B1_00 | C10: 2.16 | D10: Serial2(4) TX | G10: PWM1_A3 | I10: 1:RX_DATA | J10: IO-14 | K10: 2:16, 3:16
A11: 9 | B11: B0_11 | C11: 2.11 | G11: PWM2_B2, QT4_2 | I11: 1:TX2_RX2 | K11: 2:11
A12: 10 | B12: B0_00 | C12: 2.0 | F12: SPI(4) CS0 | G12: QT1_0 | I12: MQS_RIGHT | K12: 2:0
A13: 11 | B13: B0_02 | C13: 2.2 | F13: SPI(4) MOSI | G13: QT1_2 | H13: 1_TX | K13: 2:2
A14: 12 | B14: B0_01 | C14: 2.1 | F14: SPI(4) MISO | G14: QT1_1 | I14: MQS_LEFT | K14: 2:1
A15: 13 | B15: B0_03 | C15: 2.3 | F15: SPI(4) SCK | G15: QT2_0 | H15: 1_RX | K15: 2:3
A16: 14/A0 | B16: AD_B1_02 | C16: 1.18 | D16: Serial3(2) TX | G16: QT3_2 | I16: SPDIF_OUT | K16: 3:2 | L16: A1:7, A2:7
A17: 15/A1 | B17: AD_B1_03 | C17: 1.19 | D17: Serial3(2) RX | G17: QT3_3 | I17: SPDIF_IN | K17: 3:3 | L17: A1:8, A2:8
A18: 16/A2 | B18: AD_B1_07 | C18: 1.23 | D18: Serial4(3) RX | E18: Wire1(3) SCL | I18: SPDIF_EXTCLK | K18: 3:7 | L18: A1:12, A2:12
A19: 17/A3 | B19: AD_B1_06 | C19: 1.22 | D19: Serial4(3) TX | E19: Wire1(3) SDA | I19: SPDIF_LOCK | K19: 3:6 | L19: A1:11, A2:11
A20: 18/A4 | B20: AD_B1_01 | C20: 1.17 | D20: Serial3(2) RTS | E20: Wire(1) SDA | G20: QT3_1 | K20: 3:1 | L20: A1:6, A2:6
A21: 19/A5 | B21: AD_B1_00 | C21: 1.16 | D21: Serial3(2) CTS | E21: Wire(1) SCL | G21: QT3_0 | K21: 3:0 | L21: A1:5, A2:5
A22: 20/A6 | B22: AD_B1_10 | C22: 1.26 | D22: Serial5(8) TX | I22: 1:RX_SYNC | K22: 3:10 | L22: A1:15, A2:15
A23: 21/A7 | B23: AD_B1_11 | C23: 1.27 | D23: Serial5(8) RX | I23: 1:RX_BCLK | K23: 3:11 | L23: A1:0, A2:0
A24: 22/A8 | B24: AD_B1_08 | C24: 1.24 | G24: PWM4_A0 | H24: 1_TX | K24: 3:8 | L24: A1:13, A2:13
A25: 23/A9 | B25: AD_B1_09 | C25: 1.25 | G25: PWM4_A1 | H25: 1_RX | I25: 1:MCLK | K25: 3:9 | L25: A1:14, A2:14
A26: --- | B26: ---- | C26: ---- | D26: ------ | E26: --- | F26: --- | G26: --- | H26: --- | I26: ---- | J26: ---- | K26: ----- | L26: ------
A27: 24/A10 | B27: AD_B0_12 | C27: 1.12 | D27: Serial6(1) TX | E27: Wire2(4) SCL | G27: PWM1_X2 | L27: A1:1
A28: 25/A11 | B28: AD_B0_13 | C28: 1.13 | D28: Serial6(1) RX | E28: Wire2(4) SDA | G28: PWM1_X3 | H28: GPT1_CLK | L28: A1:2
A29: 26/A12 | B29: AD_B1_14 | C29: 1.30 | F29: SPI1(3) MOSI | I29: 1:TX_BCLK | K29: 3:14 | L29: A2:3
A30: 27/A13 | B30: AD_B1_15 | C30: 1.31 | F30: SPI1(3) SCK | I30: 1:TX_SYNC | K30: 3:15 | L30: A2:4
A31: 28 | B31: EMC_32 | C31: 3.18 | D31: Serial7(7) RX | G31: PWM3_B1
A32: 29 | B32: EMC_31 | C32: 4.31 | D32: Serial7(7) TX | F32: SPI2(1) CS1 | G32: PWM3_A1
A33: 30 | B33: EMC_37 | C33: 3.23 | G33: GPT1_3 | H33: 3_RX | I33: 3:MCLK | J33: IO-23
A34: 31 | B34: EMC_36 | C34: 3.22 | G34: GPT1_2 | H34: 3_TX | I34: 3:TX_DATA | J34: IO-22
A35: 32 | B35: B0_12 | C35: 2.12 | I35: 1:TX1_RX3 | J35: IO-10 | K35: 2:12
A36: 33 | B36: EMC_07 | C36: 4.7 | G36: PWM2_B0 | I36: 2:MCLK | J36: IO-09 | K36: 1:7
A38: 34 | B38: SD_B0_03 | C38: 3.15 | D38: Serial5(8) RTS | F38: SPI2(1) MISO | G38: PWM1_B1 | J38: IO-07 | M38: DATA1
A39: 35 | B39: SD_B0_02 | C39: 3.14 | D39: Serial5(8) CTS | F39: SPI2(1) MOSI | G39: PWM1_A1 | J39: IO-06 | M39: DATA0
A40: 36 | B40: SD_B0_01 | C40: 3.13 | E40: Wire1(3) SDA | F40: SPI2(1) CS0 | G40: PWM1_B0 | J40: IO-05 | M40: CLK
A41: 37 | B41: SD_B0_00 | C41: 3.12 | E41: Wire1(3) SCL | F41: SPI2(1) SCK | G41: PWM1_A0 | J41: IO-04 | M41: CMD
...

Sheet T4 - GPIO 
A1: Pin | B1: Name | C1: GPIO | D1: Serial | E1: I2C | F1: SPI | G1: PWM | H1: CAN | I1: Audio | J1: XBAR | K1: FlexIO | L1: Analog | M1: SD
A2: 1 | B2: AD_B0_02 | C2: 1.02 | D2: Serial1(6) TX | F2: SPI1(3) MISO | G2: PWM1_X0 | H2: 2_TX | J2: IO-16
A3: 0 | B3: AD_B0_03 | C3: 1.03 | D3: Serial1(6) RX | F3: SPI1(3) CS0 | G3: PWM1_X1 | H3: 2_RX | J3: IO-17
A4: 24/A10 | B4: AD_B0_12 | C4: 1.12 | D4: Serial6(1) TX | E4: Wire2(4) SCL | G4: PWM1_X2 | L4: A1:1
A5: 25/A11 | B5: AD_B0_13 | C5: 1.13 | D5: Serial6(1) RX | E5: Wire2(4) SDA | G5: PWM1_X3 | H5: GPT1_CLK | L5: A1:2
A6: 19/A5 | B6: AD_B1_00 | C6: 1.16 | D6: Serial3(2) CTS | E6: Wire(1) SCL | G6: QT3_0 | K6: 3:0 | L6: A1:5, A2:5
A7: 18/A4 | B7: AD_B1_01 | C7: 1.17 | D7: Serial3(2) RTS | E7: Wire(1) SDA | G7: QT3_1 | K7: 3:1 | L7: A1:6, A2:6
A8: 14/A0 | B8: AD_B1_02 | C8: 1.18 | D8: Serial3(2) TX | G8: QT3_2 | I8: SPDIF_OUT | K8: 3:2 | L8: A1:7, A2:7
A9: 15/A1 | B9: AD_B1_03 | C9: 1.19 | D9: Serial3(2) RX | G9: QT3_3 | I9: SPDIF_IN | K9: 3:3 | L9: A1:8, A2:8
A10: 17/A3 | B10: AD_B1_06 | C10: 1.22 | D10: Serial4(3) TX | E10: Wire1(3) SDA | I10: SPDIF_LOCK | K10: 3:6 | L10: A1:11, A2:11
A11: 16/A2 | B11: AD_B1_07 | C11: 1.23 | D11: Serial4(3) RX | E11: Wire1(3) SCL | I11: SPDIF_EXTCLK | K11: 3:7 | L11: A1:12, A2:12
A12: 22/A8 | B12: AD_B1_08 | C12: 1.24 | G12: PWM4_A0 | H12: 1_TX | K12: 3:8 | L12: A1:13, A2:13
A13: 23/A9 | B13: AD_B1_09 | C13: 1.25 | G13: PWM4_A1 | H13: 1_RX | I13: 1:MCLK | K13: 3:9 | L13: A1:14, A2:14
A14: 20/A6 | B14: AD_B1_10 | C14: 1.26 | D14: Serial5(8) TX | I14: 1:RX_SYNC | K14: 3:10 | L14: A1:15, A2:15
A15: 21/A7 | B15: AD_B1_11 | C15: 1.27 | D15: Serial5(8) RX | I15: 1:RX_BCLK | K15: 3:11 | L15: A1:0, A2:0
A16: 26/A12 | B16: AD_B1_14 | C16: 1.30 | F16: SPI1(3) MOSI | I16: 1:TX_BCLK | K16: 3:14 | L16: A2:3
A17: 27/A13 | B17: AD_B1_15 | C17: 1.31 | F17: SPI1(3) SCK | I17: 1:TX_SYNC | K17: 3:15 | L17: A2:4
A18: 10 | B18: B0_00 | C18: 2.00 | F18: SPI(4) CS0 | G18: QT1_0 | I18: MQS_RIGHT | K18: 2:0
A19: 12 | B19: B0_01 | C19: 2.01 | F19: SPI(4) MISO | G19: QT1_1 | I19: MQS_LEFT | K19: 2:1
A20: 11 | B20: B0_02 | C20: 2.02 | F20: SPI(4) MOSI | G20: QT1_2 | H20: 1_TX | K20: 2:2
A21: 13 | B21: B0_03 | C21: 2.03 | F21: SPI(4) SCK | G21: QT2_0 | H21: 1_RX | K21: 2:3
A22: 6 | B22: B0_10 | C22: 2.10 | G22: PWM2_A2, QT4_1 | I22: 1:TX3_RX1 | K22: 2:10
A23: 9 | B23: B0_11 | C23: 2.11 | G23: PWM2_B2, QT4_2 | I23: 1:TX2_RX2 | K23: 2:11
A24: 32 | B24: B0_12 | C24: 2.12 | I24: 1:TX1_RX3 | J24: IO-10 | K24: 2:12
A25: 8 | B25: B1_00 | C25: 2.16 | D25: Serial2(4) TX | G25: PWM1_A3 | I25: 1:RX_DATA | J25: IO-14 | K25: 2:16, 3:16
A26: 7 | B26: B1_01 | C26: 2.17 | D26: Serial2(4) RX | G26: PWM1_B3 | I26: 1:TX_DATA | J26: IO-15 | K26: 2:17, 3:17
A27: 37 | B27: SD_B0_00 | C27: 3.12 | E27: Wire1(3) SCL | F27: SPI2(1) SCK | G27: PWM1_A0 | J27: IO-04 | M27: CMD
A28: 36 | B28: SD_B0_01 | C28: 3.13 | E28: Wire1(3) SDA | F28: SPI2(1) CS0 | G28: PWM1_B0 | J28: IO-05 | M28: CLK
A29: 35 | B29: SD_B0_02 | C29: 3.14 | D29: Serial5(8) CTS | F29: SPI2(1) MOSI | G29: PWM1_A1 | J29: IO-06 | M29: DATA0
A30: 34 | B30: SD_B0_03 | C30: 3.15 | D30: Serial5(8) RTS | F30: SPI2(1) MISO | G30: PWM1_B1 | J30: IO-07 | M30: DATA1
A31: 39 | B31: SD_B0_04 | C31: 3.16 | D31: Serial5(8) TX | F31: SPI2(1) B_SSO_B | G31: PWM1_A2 | J31: IO-08 | M31: DATA2
A32: 38 | B32: SD_B0_05 | C32: 3.17 | D32: Serial5(8) RX | F32: SPI2(1) B_DQS | G32: PWM1_B2 | J32: IO-09 | M32: DATA3
A33: 28 | B33: EMC_32 | C33: 3.18 | D33: Serial7(7) RX | G33: PWM3_B1
A34: 31 | B34: EMC_36 | C34: 3.22 | G34: GPT1_2 | H34: 3_TX | I34: 3:TX_DATA | J34: IO-22
A35: 30 | B35: EMC_37 | C35: 3.23 | G35: GPT1_3 | H35: 3_RX | I35: 3:MCLK | J35: IO-23
A36: 2 | B36: EMC_04 | C36: 4.04 | G36: PWM4_A2 | I36: 2:TX_DATA | J36: IO-06 | K36: 1:4
A37: 3 | B37: EMC_05 | C37: 4.05 | G37: PWM4_B2 | I37: 2:TX_SYNC | J37: IO-07 | K37: 1:5
A38: 4 | B38: EMC_06 | C38: 4.06 | G38: PWM2_A0 | I38: 2:TX_BCLK | J38: IO-08 | K38: 1:6
A39: 33 | B39: EMC_07 | C39: 4.07 | G39: PWM2_B0 | I39: 2:MCLK | J39: IO-09 | K39: 1:7
A40: 5 | B40: EMC_08 | C40: 4.08 | G40: PWM2_A1 | I40: 2:RX_DATA | J40: IO-17 | K40: 1:8
...

Sheet T4 card like
A1: Audio | B1: Prop | C1: Native | D1: GPIO | E1: Audio | F1: FlexIO | G1: Xbar | H1: I2C | I1: CAN | J1: SPI | K1: Serial | L1: Analog | M1: PWM | N1: Digital | Q1: Digital | R1: PWM | S1: Analog | T1: Serial | U1: SPI | V1: CAN | W1: I2C | X1: Xbar | Y1: FlexIO | Z1: Audio | AA1: GPIO | AB1: Native | AC1: Prop | AD1: Audio
A2: G | B2: GND | L2: GND | Q2: Vin | AC2: 5V
C3: AD_B0_03 | D3: 1.3 | G3: 17 | I3: RX2 | J3: CS1 | K3: RX1 | M3: 1X1 | N3: 0 | Q3: GND | AC3: G | AD3: G
C4: AD_B0_02 | D4: 1.2 | G4: 16 | I4: TX2 | J4: MISO1 | K4: TX1 | M4: 1X0 | N4: 1 | Q4: 3.3V 250mA max | AC4: 3V | AD4: 3.3
B5: S | C5: EMC_04 | D5: 4.4 | E5: O2 | F5: 1:4 | G5: 6 | M5: 4A2 | N5: 2 | Q5: 23 | R5: 4A1 | S5: A9 | V5: RX1 | Y5: 3:9 | Z5: MCL1 | AA5: 1.25 | AB5: AD-B1_09 | AD5: A
A6: M | C6: EMC_05 | D6: 4.5 | E6: LR2 | F6: 1:5 | G6: 7 | M6: 4B2 | N6: 3 | Q6: 22 | R6: 4A0 | S6: A8 | V6: TX1 | Y6: 0.13055556 | AA6: 1.24 | AB6: AD_B1_08
A7: A | C7: EMC_06 | D7: 4.6 | E7: BCL2 | F7: 1:6 | G7: 8 | M7: 2A0 | N7: 4 | Q7: 21 | S7: A7 | T7: RX5 | Y7: 0.13263889 | Z7: BCL1 | AA7: 1.27 | AB7: AD_B1_11 | AD7: A
A8: A | B8: A-EN | C8: EMC_08 | D8: 4.8 | E8: IN2 | F8: 1:8 | G8: 17 | M8: 2A1 | N8: 5 | Q8: 20 | S8: A6 | T8: TX5 | Y8: 0.13194444 | Z8: LRC1 | AA8: 1.26 | AB8: AD_B1_10 | AD8: A
B9: M-CS | C9: B0_10 | D9: 2.10 | E9: O1D | F9: 2:10 | M9: 2A2, Q41 | N9: 6 | Q9: 19 | R9: Q30 | S9: A5 | T9: CTS3 | W9: SCL0 | Y9: 0.125 | AA9: 1.16 | AB9: AD_B1_00 | AC9: S | AD9: C
B10: L-EN | C10: B1_01 | D10: 2.17 | E10: O1A | F10: 2:17, 3:17 | G10: 15 | K10: RX2 | M10: 1B3 | N10: 7 | Q10: 18 | R10: Q31 | S10: A4 | W10: SDA0 | Y10: 0.12569444 | AA10: 1.17 | AB10: AD_B1_01 | AC10: S | AD10: C
C11: B1_00 | D11: 2.16 | E11: IN1 | F11: 2:16, 3:16 | G11: 14 | K11: TX2 | M11: 1A3 | N11: 8 | Q11: 17 | S11: A3 | T11: TX4 | W11: SDA1 | Y11: 0.12916667 | AA11: 1.22 | AB11: AD_B1_06
C12: B0_11 | D12: 2.11 | E12: O1C | F12: 2:11 | M12: 2B2,Q42 | N12: 9 | Q12: 16 | S12: A2 | T12: RX4 | W12: SCL1 | Y12: 0.12986111 | AA12: 1.23 | AB12: AD_B1_07
A13: S | C13: B0_00 | D13: 2.0 | E13: MQR | F13: 2:0 | J13: CS0 | M13: Q10 | N13: 10 | Q13: 15 | R13: Q33 | S13: A1 | T13: RX3 | Y13: 0.12708333 | Z13: SPDI | AA13: 1.19 | AB13: AD_B1_03 | AD13: V
A14: SM | B14: M/L | C14: B0_02 | D14: 2.2 | F14: 2:2 | I14: TX1 | J14: MOSI0 | M14: Q12 | N14: 11 | Q14: 14 | R14: Q32 | S14: A0 | T14: TX3 | Y14: 0.12638889 | Z14: SPDO | AA14: 1.18 | AB14: AD_B1_02
A15: SM | B15: M | C15: B0_01 | D15: 2.1 | E15: MQL | F15: 2:1 | J15: MISO0 | M15: Q11 | N15: 12 | Q15: 13 | R15: Q20 | S15: LED | U15: SCK0 | V15: rx1 | Y15: 0.085416667 | AA15: 2.3 | AB15: B0_03 | AC15: M | AD15: SM
K17: Bottom SMT Pins
C18: AD_B0_12 | D18: 1.12 | H18: SCL2 | K18: TX6 | L18: A10-1 | M18: 1X2 | N18: 24 | Q18: 25 | R18: 1X3 | S18: A11-1 | T18: RX6 | W18: SDA2 | AA18: 1.13 | AB18: AD_B0_13
C19: AD_B1_14 | D19: 1.30 | F19: 3:14 | J19: MOSI1 | L19: A12-2 | N19: 26 | Q19: 27 | S19: A13-2 | U19: SCK1 | Y19: 3:15 | AA19: 1.31 | AB19: AD_B1_15
C20: EMC_32 | D20: 3.18 | K20: RX7 | M20: 3B1 | N20: 28 | Q20: 29 | R20: 3A1 | T20: TX7 | AA20: 4.31 | AB20: EMC_31
C21: EMC_37 | D21: 3.23 | G21: 23 | I21: RX3 | M21: G13 | N21: 30 | Q21: 31 | R21: G12 | V21: TX3 | X21: 22 | AA21: 3.22 | AB21: EMC_36
C22: B0_12 | D22: 2.12 | E22: O1B | F22: 0.091666667 | G22: 10 | N22: 32 | Q22: 33 | R22: 2B0 | V22: TX1 | X22: 9 | Y22: 1:7 | Z22: MCL2 | AA22: 4.7 | AB22: EMC_07
K25: Bottom SDIO Pins
C27: SD_B0_03 | D27: 3.15 | F27: DATA1 | G27: 7 | J27: MISO2 | M27: 1B1 | N27: 34 | O27: ______| | P27: |_____
C28: SD_B0_02 | D28: 3.14 | F28: DATA0 | G28: 6 | J28: MOSI2 | K28: CTS5 | M28: 1A1 | N28: 35 | O28: _______| | P28: |_______
L29: GND | O29: _________| | P29: |_______
C30: SD_B0_01 | D30: 3.13 | F30: CLK | G30: 5 | H30: SDA1 | J30: CS2 | M30: 1B0 | N30: 36 | O30: __________| | P30: |___________
L31: 3.3V 250mA max
C32: SD_B0_00 | D32: 3.12 | F32: CMD | G32: 4 | H32: SCL1 | J32: SCK2 | M32: 1A0 | N32: 37
C33: SD_B0_05 | D33: 3.17 | F33: DATA3 | G33: 9 | K33: RX5 | M33: 1B2 | N33: 38
C34: SD_B0_04 | D34: 3.16 | F34: DATA2 | G34: 8 | K34: TX5 | M34: 1A2 | N34: 39

Sheet T4.1
A1: Pin | B1: Name | C1: GPIO | D1: Serial | E1: I2C | F1: SPI | G1: PWM | H1: CAN | I1: Audio | J1: XBAR | K1: FlexIO | L1: Analog | M1: SD/CSI/LCD
A2: 0 | B2: AD_B0_03 | C2: 1.3 | D2: Serial1(6) RX | F2: SPI1(3) CS0 | G2: PWM1_X1 | H2: 2_RX | J2: IO-17
A3: 1 | B3: AD_B0_02 | C3: 1.2 | D3: Serial1(6) TX | F3: SPI1(3) MISO | G3: PWM1_X0 | H3: 2_TX | J3: IO-16
A4: 2 | B4: EMC_04 | C4: 4.4 | G4: PWM4_A2 | I4: 2:TX_DATA | J4: IO-06 | K4: 1:4
A5: 3 | B5: EMC_05 | C5: 4.5 | G5: PWM4_B2 | I5: 2:TX_SYNC | J5: IO-07 | K5: 1:5
A6: 4 | B6: EMC_06 | C6: 4.6 | G6: PWM2_A0 | I6: 2:TX_BCLK | J6: IO-08 | K6: 1:6
A7: 5 | B7: EMC_08 | C7: 4.8 | G7: PWM2_A1 | I7: 2:RX_DATA | J7: IO-17 | K7: 1:8
A8: 6 | B8: B0_10 | C8: 2.10 | G8: PWM2_A2, QT4_1 | I8: 1:TX3_RX1 | K8: 2:10
A9: 7 | B9: B1_01 | C9: 2.17 | D9: Serial2(4) RX | G9: PWM1_B3 | I9: 1:TX_DATA | J9: IO-15 | K9: 2:17, 3:17
A10: 8 | B10: B1_00 | C10: 2.16 | D10: Serial2(4) TX | G10: PWM1_A3 | I10: 1:RX_DATA | J10: IO-14 | K10: 2:16, 3:16
A11: 9 | B11: B0_11 | C11: 2.11 | G11: PWM2_B2,QT4_2 | I11: 1:TX2_RX2 | K11: 2:11
A12: 10 | B12: B0_00 | C12: 2.0 | F12: SPI(4) CS0 | G12: QT1_0 | I12: MQS_RIGHT | K12: 2:0
A13: 11 | B13: B0_02 | C13: 2.2 | F13: SPI(4) MOSI | G13: QT1_2 | H13: 1_TX | K13: 2:2
A14: 12 | B14: B0_01 | C14: 2.1 | F14: SPI(4) MISO | G14: QT1_1 | I14: MQS_LEFT | K14: 2:1
A15: 13 | B15: B0_03 | C15: 2.3 | F15: SPI(4) SCK | G15: QT2_0 | H15: 1_RX | K15: 2:3
A16: 14/A0 | B16: AD_B1_02 | C16: 1.18 | D16: Serial3(2) TX | G16: QT3_2 | I16: SPDIF_OUT | K16: 3:2 | L16: A1:7, A2:7
A17: 15/A1 | B17: AD_B1_03 | C17: 1.19 | D17: Serial3(2) RX | G17: QT3_3 | I17: SPDIF_IN | K17: 3:3 | L17: A1:8, A2:8
A18: 16/A2 | B18: AD_B1_07 | C18: 1.23 | D18: Serial4(3) RX | E18: Wire1(3) SCL | I18: SPDIF_EXTCLK | K18: 3:7 | L18: A1:12, A2:12 | M18: CSI_HSYNC
A19: 17/A3 | B19: AD_B1_06 | C19: 1.22 | D19: Serial4(3) TX | E19: Wire1(3) SDA | I19: SPDIF_LOCK | K19: 3:6 | L19: A1:11, A2:11 | M19: CSI_VSYNC
A20: 18/A4 | B20: AD_B1_01 | C20: 1.17 | D20: Serial3(2) RTS | E20: Wire(1) SDA | G20: QT3_1 | K20: 3:1 | L20: A1:6, A2:6
A21: 19/A5 | B21: AD_B1_00 | C21: 1.16 | D21: Serial3(2) CTS | E21: Wire(1) SCL | G21: QT3_0 | K21: 3:0 | L21: A1:5, A2:5
A22: 20/A6 | B22: AD_B1_10 | C22: 1.26 | D22: Serial5(8) TX | I22: 1:RX_SYNC | K22: 3:10 | L22: A1:15, A2:15 | M22: CSI_D7
A23: 21/A7 | B23: AD_B1_11 | C23: 1.27 | D23: Serial5(8) RX | I23: 1:RX_BCLK | K23: 3:11 | L23: A1:0, A2:0 | M23: CSI_D6
A24: 22/A8 | B24: AD_B1_08 | C24: 1.24 | G24: PWM4_A0 | H24: 1_TX | K24: 3:8 | L24: A1:13, A2:13 | M24: CSI_D9
A25: 23/A9 | B25: AD_B1_09 | C25: 1.25 | G25: PWM4_A1 | H25: 1_RX | I25: 1:MCLK | K25: 3:9 | L25: A1:14, A2:14 | M25: CSI_D8
A26: --- | B26: ---- | C26: ---- | D26: ------ | E26: --- | F26: --- | G26: --- | H26: --- | I26: ---- | J26: ---- | K26: ----- | L26: ------
A27: 24/A10 | B27: AD_B0_12 | C27: 1.12 | D27: Serial6(1) TX | E27: Wire2(4) SCL | G27: PWM1_X2 | L27: A1:1
A28: 25/A11 | B28: AD_B0_13 | C28: 1.13 | D28: Serial6(1) RX | E28: Wire2(4) SDA | G28: PWM1_X3 | H28: GPT1_CLK | L28: A1:2
A29: 26/A12 | B29: AD_B1_14 | C29: 1.30 | F29: SPI1(3) MOSI | I29: 1:TX_BCLK | K29: 3:14 | L29: A2:3 | M29: CSI_D3
A30: 27/A13 | B30: AD_B1_15 | C30: 1.31 | F30: SPI1(3) SCK | I30: 1:TX_SYNC | K30: 3:15 | L30: A2:4 | M30: CSI_D2
A31: 28 | B31: EMC_32 | C31: 3.18 | D31: Serial7(7) RX | G31: PWM3_B1
A32: 29 | B32: EMC_31 | C32: 4.31 | D32: Serial7(7) TX | F32: SPI2(1) CS1 | G32: PWM3_A1
A33: 30 | B33: EMC_37 | C33: 3.23 | G33: GPT1_3 | H33: 3_RX | I33: 3:MCLK | J33: IO-23
A34: 31 | B34: EMC_36 | C34: 3.22 | G34: GPT1_2 | H34: 3_TX | I34: 3:TX_DATA | J34: IO-22
A35: 32 | B35: B0_12 | C35: 2.12 | I35: 1:TX1_RX3 | J35: IO-10 | K35: 2:12
A36: 33 | B36: EMC_07 | C36: 4.7 | G36: PWM2_B0 | I36: 2:MCLK | J36: IO-09 | K36: 1:7
A37: 34 | B37: B1_13 | C37: 2.29 | D37: Serial8(5) RX | K37: 2:29,3:29
A38: 35 | B38: B1_12 | C38: 2.28 | D38: Serial8(5) TX | K38: 2:28,3:28
A39: 36 | B39: B1_02 | C39: 2.18 | F39: SPI(4) CS2 | G39: PWM2_A3 | I39: 1:TX_BCLK | J39: IO-16 | K39: 2:18,3:18
A40: 37 | B40: B1_03 | C40: 2.19 | F40: SPI(4) CS1 | G40: PWM2_B3 | I40: 1:TX_SYNC | J40: IO-17 | K40: 2:19,3:19
...

Sheet T4.1 MUX
A1: Pin | B1: Name | C1: ALT0 | D1: ALt1 | E1: ALT2 | F1: ALT3 | G1: ALT4 | H1: Alt5 | I1: ALT6 | J1: ALT7 | K1: ALT8 | L1: ALT9
A2: 0 | B2: AD_B0_03 | C2: FLEXCAN2_RX | D2: XBAR1_INOUT17 | E2: LPUART6_RX | F2: USB_OTG1_OC | G2: FLEXPWM1_PWMX01 | H2: GPIO1_IO03 | I2: REF_CLK_24M | J2: LPSPI3_PCS0
A3: 1 | B3: AD_B0_02 | C3: FLEXCAN2_TX | D3: XBAR1_INOUT16 | E3: LPUART6_TX | F3: USB_OTG1_PWR | G3: LEXPWM1_PWMX0 | H3: GPIO1_IO02 | I3: LPI2C1_HREQ | J3: LPSPI3_SDI
A4: 2 | B4: EMC_04 | C4: SEMC_DATA04 | D4: FLEXPWM4_PWMA02 | E4: SAI2_TX_DATA | F4: XBAR1_INOUT06 | G4: FLEXIO1_FLEXIO04 | H4: GPIO4_IO04
A5: 3 | B5: EMC_05 | C5: SEMC_DATA05 | D5: FLEXPWM4_PWMB02 | E5: SAI2_TX_SYNC | F5: XBAR1_INOUT07 | G5: FLEXIO1_FLEXIO05 | H5: GPIO4_IO05
A6: 4 | B6: EMC_06 | C6: SEMC_DATA06 | D6: FLEXPWM2_PWMA00 | E6: SAI2_TX_BCLK | F6: XBAR1_INOUT08 | G6: FLEXIO1_FLEXIO06 | H6: GPIO4_IO06
A7: 5 | B7: EMC_08 | C7: SEMC_DM00 | D7: FLEXPWM2_PWMA01 | E7: SAI2_RX_DATA | F7: XBAR1_INOUT17 | G7: FLEXIO1_FLEXIO08 | H7: GPIO4_IO08
A8: 6 | B8: B0_10 | C8: LCD_DATA06 | D8: QTIMER4_TIMER1 | E8: FLEXPWM2_PWMA02 | F8: SAI1_TX_DATA03 | G8: FLEXIO2_FLEXIO10 | H8: GPIO2_IO10 | I8: SRC_BOOT_CFG06 | K8: ENET2_CRS
A9: 7 | B9: B1_01 | C9: LCD_DATA13 | D9: XBAR1_INOUT15 | E9: LPUART4_RX | F9: SAI1_TX_DATA00 | G9: FLEXIO2_FLEXIO17 | H9: GPIO2_IO17 | I9: FLEXPWM1_PWMB03 | K9: ENET2_RDATA00 | L9: FLEXIO3_FLEXIO17
A10: 8 | B10: B1_00 | C10: LCD_DATA12 | D10: XBAR1_INOUT14 | E10: LPUART4_TX | F10: SAI1_RX_DATA00 | G10: FLEXIO2_FLEXIO16 | H10: GPIO2_IO16 | I10: FLEXPWM1_PWMA03 | K10: ENET2_RX_ER | L10: FLEXIO3_FLEXIO16
A11: 9 | B11: B0_11 | C11: LCD_DATA07 | D11: QTIMER4_TIMER2 | E11: FLEXPWM2_PWMB02 | F11: SAI1_TX_DATA02 | G11: FLEXIO2_FLEXIO11 | H11: GPIO2_IO11 | I11: SRC_BOOT_CFG07 | K11: ENET2_COL
A12: 10 | B12: B0_00 | C12: LCD_CLK | D12: QTIMER1_TIMER0 | E12: MQS_RIGHT | F12: LPSPI4_PCS0 | G12: FLEXIO2_FLEXIO00 | H12: GPIO2_IO00 | I12: SEMC_CSX01 | K12: ENET2_MDC
A13: 11 | B13: B0_02 | C13: LCD_HSYNC | D13: QTIMER1_TIMER2 | E13: FLEXCAN1_TX | F13: LPSPI4_SDO | G13: FLEXIO2_FLEXIO02 | H13: GPIO2_IO02 | I13: SEMC_CSX03 | K13: ENET2_1588_EVENT0_OUT
A14: 12 | B14: B0_01 | C14: LCD_ENABLE | D14: QTIMER1_TIMER1 | E14: MQS_LEFT | F14: LPSPI4_SDI | G14: FLEXIO2_FLEXIO01 | H14: GPIO2_IO01 | I14: SEMC_CSX02 | K14: ENET2_MDIO
A15: 13 | B15: B0_03 | C15: LCD_VSYNC | D15: QTIMER2_TIMER0 | E15: FLEXCAN1_RX | F15: LPSPI4_SCK | G15: FLEXIO2_FLEXIO03 | H15: GPIO2_IO03 | I15: WDOG2_RESET_B_DEB | K15: ENET2_1588_EVENT0_IN
A16: 14/A0 | B16: AD_B1_02 | C16: USB_OTG1_ID | D16: QTIMER3_TIMER2 | E16: LPUART2_TX | F16: SPDIF_OUT | G16: ENET_1588_EVENT2_OUT | H16: GPIO1_IO18 | I16: USDHC1_CD_B | J16: KPP_ROW06 | K16: GPT2_CLK | L16: FLEXIO3_FLEXIO02
A17: 15/A1 | B17: AD_B1_03 | C17: USB_OTG1_OC | D17: QTIMER3_TIMER3 | E17: LPUART2_RX | F17: SPDIF_IN | G17: ENET_1588_EVENT2_IN | H17: GPIO1_IO19 | I17: USDHC2_CD_B | J17: KPP_COL06 | K17: GPT2_CAPTURE1 | L17: FLEXIO3_FLEXIO03
A18: 16/A2 | B18: AD_B1_07 | C18: FLEXSPIB_DATA00 | D18: LPI2C3_SCL | E18: LPUART3_RX | F18: SPDIF_EXT_CLK | G18: CSI_HSYNC | H18: GPIO1_IO23 | I18: USDHC2_DATA3 | J18: KPP_COL04 | K18: GPT2_COMPARE3 | L18: FLEXIO3_FLEXIO07
A19: 17/A3 | B19: AD_B1_06 | C19: FLEXSPIB_DATA01 | D19: LPI2C3_SDA | E19: LPUART3_TX | F19: SPDIF_LOCK | G19: CSI_VSYNC | H19: GPIO1_IO22 | I19: USDHC2_DATA2 | J19: KPP_ROW04 | K19: GPT2_COMPARE2 | L19: FLEXIO3_FLEXIO06
A20: 18/A4 | B20: AD_B1_01 | C20: USB_OTG1_PWR | D20: QTIMER3_TIMER1 | E20: LPUART2_RTS_B | F20: LPI2C1_SDA | G20: CCM_PMIC_READY | H20: GPIO1_IO17 | I20: USDHC1_VSELECT | J20: KPP_COL07 | K20: ENET2_1588_EVENT0_IN | L20: FLEXIO3_FLEXIO01
A21: 19/A5 | B21: AD_B1_00 | C21: USB_OTG2_ID | D21: QTIMER3_TIMER0 | E21: LPUART2_CTS_B | F21: LPI2C1_SCL | G21: WDOG1_B | H21: GPIO1_IO16 | I21: USDHC1_W | J21: KPP_ROW07 | K21: ENET2_1588_EVENT0_OUT | L21: FLEXIO3_FLEXIO00
A22: 20/A6 | B22: AD_B1_10 | C22: FLEXSPIA_DATA03 | D22: WDOG1_B | E22: LPUART8_TX | F22: SAI1_RX_SYNC | G22: CSI_DATA07 | H22: GPIO1_IO26 | I22: USDHC2_WP | J22: KPP_ROW02 | K22: ENET2_1588_EVENT1_OUT | L22: FLEXIO3_FLEXIO10
A23: 21/A7 | B23: AD_B1_11 | C23: FLEXSPIA_DATA02 | D23: EWM_OUT_B | E23: LPUART8_RX | F23: SAI1_RX_BCL | G23: CSI_DATA06 | H23: GPIO1_IO27 | I23: USDHC2_RESET_B | J23: KPP_COL02 | K23: ENET2_1588_EVENT1_IN | L23: FLEXIO3_FLEXIO11
A24: 22/A8 | B24: AD_B1_08 | C24: FLEXSPIA_SS1_B | D24: FLEXPWM4_PWMA00 | E24: FLEXCAN1_TX | F24: CCM_PMIC_READY | G24: CSI_DATA09 | H24: GPIO1_IO24 | I24: USDHC2_CMD | J24: KPP_ROW03 | L24: FLEXIO3_FLEXIO08
A25: 23/A9 | B25: AD_B1_09 | C25: FLEXSPIA_DQS | D25: FLEXPWM4_PWMA01 | E25: FLEXCAN1_RX | F25: SAI1_MCLK | G25: CSI_DATA08 | H25: GPIO1_IO25 | I25: USDHC2_CLK | J25: KPP_COL03 | L25: FLEXIO3_FLEXIO09
A26: 24/A10 | B26: AD_B0_12 | C26: LPI2C4_SCL | D26: CCM_PMIC_READY | E26: LPUART1_TX | F26: WDOG2_WDOG_B | G26: FLEXPWM1_PWMX02 | H26: GPIO1_IO12 | I26: ENET_1588_EVENT1_OUT | J26: NMI_GLUE_NMI
A27: 25/A11 | B27: AD_B0_13 | C27: LPI2C4_SDA | D27: GPT1_CLK | E27: LPUART1_RX | F27: EWM_OUT_B | G27: FLEXPWM1_PWMX03 | H27: GPIO1_IO13 | I27: ENET_1588_EVENT1_IN | J27: REF_CLK_24M
A28: 26/A12 | B28: AD_B1_14 | C28: FLEXSPIA_SCLK | D28: ACMP_OUT02 | E28: LPSPI3_SDO | F28: SAI1_TX_BCLK | G28: CSI_DATA03 | H28: GPIO1_IO30 | I28: USDHC2_DATA6 | J28: KPP_ROW00 | K28: ENET2_1588_EVENT3_OUT | L28: FLEXIO3_FLEXIO14
A29: 27/A13 | B29: AD_B1_15 | C29: FLEXSPIA_SS0_B | D29: ACMP_OUT03 | E29: LPSPI3_SCK | F29: SAI1_TX_SYNC | G29: CSI_DATA02 | H29: GPIO1_IO31 | I29: USDHC2_DATA7 | J29: KPP_COL00 | K29: ENET2_1588_EVENT3_IN | L29: FLEXIO3_FLEXIO15
A30: 28 | B30: EMC_32 | C30: SEMC_DATA10 | D30: FLEXPWM3_PWMB01 | E30: LPUART7_RX | F30: CCM_PMIC_RDY | G30: CSI_DATA21 | H30: GPIO3_IO18 | K30: ENET2_TX_EN
A31: 29 | B31: EMC_31 | C31: SEMC_DATA09 | D31: FLEXPWM3_PWMA01 | E31: LPUART7_TX | F31: LPSPI1_PCS1 | G31: CSI_DATA22 | H31: GPIO4_IO31 | K31: ENET2_TDATA01
A32: 30 | B32: EMC_37 | C32: SEMC_DATA15 | D32: XBAR1_IN23 | E32: GPT1_COMPARE3 | F32: SAI3_MCLK | G32: CSI_DATA16 | H32: GPIO3_IO23 | I32: USDHC2_WP | K32: ENET2_RX_EN | L32: FLEXCAN3_RX
A33: 31 | B33: EMC_36 | C33: SEMC_DATA14 | D33: XBAR1_IN22 | E33: GPT1_COMPARE2 | F33: SAI3_TX_DATA | G33: CSI_DATA17 | H33: GPIO3_IO22 | I33: USDHC1_WP | K33: ENET2_RDATA01 | L33: FLEXCAN3_TX
A34: 32 | B34: B0_12 | C34: LCD_DATA08 | D34: XBAR1_INOUT10 | E34: ARM_TRACE_CLK | F34: SAI1_TX_DATA01 | G34: FLEXIO2_FLEXIO12 | H34: GPIO2_IO12 | I34: SRC_BOOT_CFG08 | K34: ENET2_TDATA00
A35: 33 | B35: EMC_07 | C35: SEMC_DATA07 | D35: FLEXPWM2_PWMB00 | E35: SAI2_MCLK | F35: XBAR1_INOUT09 | G35: FLEXIO1_FLEXIO07 | H35: GPIO4_IO07
A36: 34 | B36: B1_13 | C36: WDOG1_B | D36: LPUART5_RX | E36: CSI_VSYNC | F36: ENET_1588_EVENT0_OUT | G36: FLEXIO2_FLEXIO29 | H36: GPIO2_IO29 | I36: USDHC1_WP | K36: SEMC_DQS4 | L36: FLEXIO3_FLEXIO29
A37: 35 | B37: B1_12 | D37: LPUART5_TX | E37: CSI_PIXCLK | F37: ENET_1588_EVENT0_IN | G37: FLEXIO2_FLEXIO28 | H37: GPIO2_IO28 | I37: USDHC1_CD_B | L37: FLEXIO3_FLEXIO28
A38: 36 | B38: B1_02 | C38: LCD_DATA14 | D38: XBAR1_INOUT16 | E38: LPSPI4_PCS2 | F38: SAI1_TX_BCLK | G38: FLEXIO2_FLEXIO18 | H38: GPIO2_IO18 | I38: FLEXPWM2_PWMA03 | K38: ENET2_RDATA01 | L38: FLEXIO3_FLEXIO18
A39: 37 | B39: B1_03 | C39: LCD_DATA15 | D39: XBAR1_INOUT17 | E39: LPSPI4_PCS1 | F39: SAI1_TX_SYNC | G39: FLEXIO2_FLEXIO19 | H39: GPIO2_IO19 | I39: FLEXPWM2_PWMB03 | K39: ENET2_RX_EN | L39: FLEXIO3_FLEXIO19
A40: 38/A14 | B40: AD_B1_12 | C40: FLEXSPIA_DATA01 | D40: ACMP_OUT00 | E40: LPSPI3_PCS0 | F40: SAI1_RX_DATA00 | G40: CSI_DATA05 | H40: GPIO1_IO28 | I40: USDHC2_DATA4 | J40: KPP_ROW01 | K40: ENET2_1588_EVENT2_OUT | L40: FLEXIO3_FLEXIO12
...

Sheet T4.1 - GPIO
A1: Pin | B1: Name | C1: GPIO | D1: Serial | E1: I2C | F1: SPI | G1: PWM | H1: CAN | I1: Audio | J1: XBAR | K1: FlexIO | L1: Analog | M1: SD/CSI/LCD
A2: 1 | B2: AD_B0_02 | C2: 1.02 | D2: Serial1(6) TX | F2: SPI1(3) MISO | G2: PWM1_X0 | H2: 2_TX | J2: IO-16
A3: 0 | B3: AD_B0_03 | C3: 1.03 | D3: Serial1(6) RX | F3: SPI1(3) CS0 | G3: PWM1_X1 | H3: 2_RX | J3: IO-17
A4: 24/A10 | B4: AD_B0_12 | C4: 1.12 | D4: Serial6(1) TX | E4: Wire2(4) SCL | G4: PWM1_X2 | L4: A1:1
A5: 25/A11 | B5: AD_B0_13 | C5: 1.13 | D5: Serial6(1) RX | E5: Wire2(4) SDA | G5: PWM1_X3 | H5: GPT1_CLK | L5: A1:2
A6: 19/A5 | B6: AD_B1_00 | C6: 1.16 | D6: Serial3(2) CTS | E6: Wire(1) SCL | G6: QT3_0 | K6: 3:0 | L6: A1:5, A2:5
A7: 18/A4 | B7: AD_B1_01 | C7: 1.17 | D7: Serial3(2) RTS | E7: Wire(1) SDA | G7: QT3_1 | K7: 3:1 | L7: A1:6, A2:6
A8: 14/A0 | B8: AD_B1_02 | C8: 1.18 | D8: Serial3(2) TX | G8: QT3_2 | I8: SPDIF_OUT | K8: 3:2 | L8: A1:7, A2:7
A9: 15/A1 | B9: AD_B1_03 | C9: 1.19 | D9: Serial3(2) RX | G9: QT3_3 | I9: SPDIF_IN | K9: 3:3 | L9: A1:8, A2:8
A10: 40/A16 | B10: AD_B1_04 | C10: 1.20 | K10: 3:4 | L10: A1:9,A2:9 | M10: USDHC2_DATA0
A11: 41/A17 | B11: AD_B1_05 | C11: 1.21 | G11: GPT2_1 | K11: 3:5 | L11: A1:10,A2:10 | M11: USDHC2_DATA1
A12: 17/A3 | B12: AD_B1_06 | C12: 1.22 | D12: Serial4(3) TX | E12: Wire1(3) SDA | I12: SPDIF_LOCK | K12: 3:6 | L12: A1:11, A2:11 | M12: USDHC2_DATA2
A13: 16/A2 | B13: AD_B1_07 | C13: 1.23 | D13: Serial4(3) RX | E13: Wire1(3) SCL | I13: SPDIF_EXTCLK | K13: 3:7 | L13: A1:12, A2:12 | M13: USDHC2_DATA3
A14: 22/A8 | B14: AD_B1_08 | C14: 1.24 | G14: PWM4_A0 | H14: 1_TX | K14: 3:8 | L14: A1:13, A2:13 | M14: USDHC2_CMD
A15: 23/A9 | B15: AD_B1_09 | C15: 1.25 | G15: PWM4_A1 | H15: 1_RX | I15: 1:MCLK | K15: 3:9 | L15: A1:14, A2:14 | M15: USDHC2_CLK
A16: 20/A6 | B16: AD_B1_10 | C16: 1.26 | D16: Serial5(8) TX | I16: 1:RX_SYNC | K16: 3:10 | L16: A1:15, A2:15
A17: 21/A7 | B17: AD_B1_11 | C17: 1.27 | D17: Serial5(8) RX | I17: 1:RX_BCLK | K17: 3:11 | L17: A1:0, A2:0
A18: 38/A14 | B18: AD_B1_12 | C18: 1.28 | F18: SPI1(3) CS0 | I18: 1:rx_data | K18: 3:12 | L18: A2:1
A19: 39/A5 | B19: AD_B1_13 | C19: 1.29 | F19: SPI1(3) MISO | I19: 1:tx_data | K19: 3:13 | L19: A2:2
A20: 26/A12 | B20: AD_B1_14 | C20: 1.30 | F20: SPI1(3) MOSI | I20: 1:TX_BCLK | K20: 3:14 | L20: A2:3
A21: 27/A13 | B21: AD_B1_15 | C21: 1.31 | F21: SPI1(3) SCK | I21: 1:TX_SYNC | K21: 3:15 | L21: A2:4
A22: 10 | B22: B0_00 | C22: 2.00 | F22: SPI(4) CS0 | G22: QT1_0 | I22: MQS_RIGHT | K22: 2:0
A23: 12 | B23: B0_01 | C23: 2.01 | F23: SPI(4) MISO | G23: QT1_1 | I23: MQS_LEFT | K23: 2:1
A24: 11 | B24: B0_02 | C24: 2.02 | F24: SPI(4) MOSI | G24: QT1_2 | H24: 1_TX | K24: 2:2
A25: 13 | B25: B0_03 | C25: 2.03 | F25: SPI(4) SCK | G25: QT2_0 | H25: 1_RX | K25: 2:3
A26: 6 | B26: B0_10 | C26: 2.10 | G26: PWM2_A2, QT4_1 | I26: 1:TX3_RX1 | K26: 2:10
A27: 9 | B27: B0_11 | C27: 2.11 | G27: PWM2_B2,QT4_2 | I27: 1:TX2_RX2 | K27: 2:11
A28: 32 | B28: B0_12 | C28: 2.12 | I28: 1:TX1_RX3 | J28: IO-10 | K28: 2:12
A29: 8 | B29: B1_00 | C29: 2.16 | D29: Serial2(4) TX | G29: PWM1_A3 | I29: 1:RX_DATA | J29: IO-14 | K29: 2:16, 3:16
A30: 7 | B30: B1_01 | C30: 2.17 | D30: Serial2(4) RX | G30: PWM1_B3 | I30: 1:TX_DATA | J30: IO-15 | K30: 2:17, 3:17
A31: 36 | B31: B1_02 | C31: 2.18 | F31: SPI(4) CS2 | G31: PWM2_A3 | I31: 1:TX_BCLK | J31: IO-16 | K31: 2:18,3:18
A32: 37 | B32: B1_03 | C32: 2.19 | F32: SPI(4) CS1 | G32: PWM2_B3 | I32: 1:TX_SYNC | J32: IO-17 | K32: 2:19,3:19
A33: 35 | B33: B1_12 | C33: 2.28 | D33: Serial8(5) TX | K33: 2:28,3:28
A34: 34 | B34: B1_13 | C34: 2.29 | D34: Serial8(5) RX | K34: 2:29,3:29
A35: 45 | B35: SD_B0_00 | C35: 3.12 | E35: Wire1(3) SCL | F35: SPI2(1) SCK | G35: PWM1_A0 | J35: IO-04 | M35: CMD
A36: 44 | B36: SD_B0_01 | C36: 3.13 | E36: Wire1(3) SDA | F36: SPI2(1) CS0 | G36: PWM1_B0 | J36: IO-05 | M36: CLK
A37: 43 | B37: SD_B0_02 | C37: 3.14 | D37: Serial5(8) CTS | F37: SPI2(1) MOSI | G37: PWM1_A1 | J37: IO-06 | M37: DATA0
A38: 42 | B38: SD_B0_03 | C38: 3.15 | D38: Serial5(8) RTS | F38: SPI2(1) MISO | G38: PWM1_B1 | J38: IO-07 | M38: DATA1
A39: 47 | B39: SD_B0_04 | C39: 3.16 | D39: Serial5(8) TX | F39: FLEXSPI B_SSO_B | G39: PWM1_A2 | J39: IO-08 | M39: DATA2
A40: 46 | B40: SD_B0_05 | C40: 3.17 | D40: Serial5(8) RX | F40: FLEXSPI B_DQS | G40: PWM1_B2 | J40: IO-09 | M40: DATA3
...

Sheet T4.1 card like
A1: Audio | B1: Prop | C1: Native | D1: GPIO | E1: Audio | F1: FlexIO | G1: Xbar | H1: I2C | I1: CAN | J1: SPI | K1: Serial | L1: Analog | M1: PWM | N1: Digital | Q1: Digital | R1: PWM | S1: Analog | T1: Serial | U1: SPI | V1: CAN | W1: I2C | X1: Xbar | Y1: FlexIO | Z1: Audio | AA1: GPIO | AB1: Native | AC1: Prop | AD1: Audio
A2: G | B2: GND | L2: GND | Q2: Vin | AC2: 5V
C3: AD_B0_03 | D3: 1.3 | G3: 17 | I3: RX2 | J3: CS1 | K3: RX1 | M3: 1X1 | N3: 0 | Q3: GND | AC3: G | AD3: G
C4: AD_B0_02 | D4: 1.2 | G4: 16 | I4: TX2 | J4: MISO1 | K4: TX1 | M4: 1X0 | N4: 1 | Q4: 3.3V 250mA max | AC4: 3V | AD4: 3.3
B5: S | C5: EMC_04 | D5: 4.4 | E5: O2 | F5: 1:4 | G5: 6 | M5: 4A2 | N5: 2 | Q5: 23 | R5: 4A1 | S5: A9 | V5: RX1 | Y5: 3:9 | Z5: MCL1 | AA5: 1.25 | AB5: AD_B1_09 | AC5: CSI_D8 | AD5: A
A6: M | C6: EMC_05 | D6: 4.5 | E6: LR2 | F6: 1:5 | G6: 7 | M6: 4B2 | N6: 3 | Q6: 22 | R6: 4A0 | S6: A8 | V6: TX1 | Y6: 0.13055556 | AA6: 1.24 | AB6: AD_B1_08 | AC6: CSI_D9
A7: A | C7: EMC_06 | D7: 4.6 | E7: BCL2 | F7: 1:6 | G7: 8 | M7: 2A0 | N7: 4 | Q7: 21 | S7: A7 | T7: RX5 | Y7: 0.13263889 | Z7: BCL1 | AA7: 1.27 | AB7: AD_B1_11 | AC7: CSI_D6 | AD7: A
A8: A | B8: A-EN | C8: EMC_08 | D8: 4.8 | E8: IN2 | F8: 1:8 | G8: 17 | M8: 2A1 | N8: 5 | Q8: 20 | S8: A6 | T8: TX5 | Y8: 0.13194444 | Z8: LRC1 | AA8: 1.26 | AB8: AD_B1_10 | AC8: CSI_D7 | AD8: A
B9: M-CS | C9: B0_10 | D9: 2.10 | E9: O1D | F9: 2:10 | M9: 2A2, Q41 | N9: 6 | Q9: 19 | R9: Q30 | S9: A5 | T9: CTS3 | W9: SCL0 | Y9: 0.125 | AA9: 1.16 | AB9: AD_B1_00 | AC9: S | AD9: C
B10: L-EN | C10: B1_01 | D10: 2.17 | E10: O1A | F10: 2:17, 3:17 | G10: 15 | K10: RX2 | M10: 1B3 | N10: 7 | Q10: 18 | R10: Q31 | S10: A4 | W10: SDA0 | Y10: 0.12569444 | AA10: 1.17 | AB10: AD_B1_01 | AC10: S | AD10: C
C11: B1_00 | D11: 2.16 | E11: IN1 | F11: 2:16, 3:16 | G11: 14 | K11: TX2 | M11: 1A3 | N11: 8 | Q11: 17 | S11: A3 | T11: TX4 | W11: SDA1 | Y11: 0.12916667 | AA11: 1.22 | AB11: AD_B1_06 | AC11: CSI_VSYNC
C12: B0_11 | D12: 2.11 | E12: O1C | F12: 2:11 | M12: 2B2,Q42 | N12: 9 | Q12: 16 | S12: A2 | T12: RX4 | W12: SCL1 | Y12: 0.12986111 | AA12: 1.23 | AB12: AD_B1_07 | AC12: CSI_HSYNC
A13: S | C13: B0_00 | D13: 2.0 | E13: MQR | F13: 2:0 | J13: CS0 | M13: Q10 | N13: 10 | Q13: 15 | R13: Q33 | S13: A1 | T13: RX3 | Y13: 0.12708333 | Z13: SPDI | AA13: 1.19 | AB13: AD_B1_03 | AD13: V
A14: SM | B14: M/L | C14: B0_02 | D14: 2.2 | F14: 2:2 | I14: TX1 | J14: MOSI0 | M14: Q12 | N14: 11 | Q14: 14 | R14: Q32 | S14: A0 | T14: TX3 | Y14: 0.12638889 | Z14: SPDO | AA14: 1.18 | AB14: AD_B1_02
A15: SM | B15: M | C15: B0_01 | D15: 2.1 | E15: MQL | F15: 2:1 | J15: MISO0 | M15: Q11 | N15: 12 | Q15: 13 | R15: Q20 | S15: LED | U15: SCK0 | V15: rx1 | Y15: 0.085416667 | AA15: 2.3 | AB15: B0_03 | AC15: M | AD15: SM
L16: 3.3V | Q16: GND
C17: AD_B0_12 | D17: 1.12 | H17: SCL2 | K17: TX6 | L17: A10-1 | M17: 1X2 | N17: 24 | Q17: 41 | R17: GPT2-1 | S17: A17 | Y17: 3:5 | AA17: 1.21 | AB17: AD_B1_05 | AC17: CSI_MCLK
C18: AD_B0_13 | D18: 1.13 | H18: SDA2 | K18: RX6 | L18: A11-1 | M18: 1X3 | N18: 25 | Q18: 40 | R18: GPT2-2 | S18: A16 | Y18: 3:4 | AA18: 1.20 | AB18: AD_B1_04 | AC18: CSI_PIXCLK
B19: CSI_D3 | C19: AD_B1_14 | D19: 1.30 | F19: 3:14 | J19: MOSI1 | L19: A12-2 | N19: 26 | Q19: 39 | S19: A15-2 | U19: MISO1 | Y19: 3:13 | AA19: 1.29 | AB19: AD_B1_13 | AC19: CSI_D4
B20: CSI_D2 | C20: AD_B1_15 | D20: 1.31 | F20: 3:15 | J20: SCK1 | L20: A13-2 | N20: 27 | Q20: 38 | S20: A14-2 | U20: CS1-0 | Y20: 3:12 | AA20: 1.28 | AB20: AD_B1_12 | AC20: CSI_D5
C21: EMC_32 | D21: 3.18 | K21: RX7 | M21: 3B1 | N21: 28 | Q21: 37 | R21: 2B3 | U21: CS0-1 | X21: 17 | Y21: 2:19,3:19 | AA21: 2.19 | AB21: B1_03
C22: EMC_31 | D22: 4.31 | K22: TX7 | M22: 3A1 | N22: 29 | Q22: 36 | R22: 2A3 | U22: CS0-2 | X22: 16 | Y22: 2:18,3:18 | AA22: 2.18 | AB22: B1_02
C23: EMC_37 | D23: 3.23 | G23: 23 | I23: RX3 | M23: G13 | N23: 30 | Q23: 35 | T23: TX8 | Y23: 2:28,3:28 | AA23: 2.28 | AB23: B1_12 | AC23: CSI_PIXCLK
C24: EMC_36 | D24: 3.22 | G24: 22 | I24: TX3 | M24: G12 | N24: 31 | Q24: 34 | T24: RX8 | Y24: 2:29,3:29 | AA24: 2.29 | AB24: B1_13 | AC24: CSI_VSYNC
C25: B0_12 | D25: 2.12 | E25: O1B | F25: 0.091666667 | G25: 10 | N25: 32 | Q25: 33 | R25: 2B0 | X25: 9 | Y25: 1:7 | Z25: MCL2 | AA25: 4.7 | AB25: EMC_07
O27: SDIO Pins
C28: SD_B0_03 | D28: 3.15 | F28: DATA1 | G28: 7 | J28: MISO2 | M28: 1B1 | N28: 42 | O28: ______| | P28: |_____ | Q28: 47 | R28: 1A2 | T28: TX5 | X28: 8 | Y28: DATA2 | AA28: 3.16 | AB28: SD_B0_04
C29: SD_B0_02 | D29: 3.14 | F29: DATA0 | G29: 6 | J29: MOSI2 | K29: CTS5 | M29: 1A1 | N29: 43 | O29: _______| | P29: |_______ | Q29: 46 | R29: 1B2 | T29: RX5 | X29: 9 | Y29: DATA3 | AA29: 3.17 | AB29: SD_B0_05
L30: GND | O30: _________| | P30: |_______ | Q30: 45 | R30: 1A0 | U30: SCK2 | W30: SCL1 | X30: 4 | Y30: CMD | AA30: 3.12 | AB30: SD_B0_00
C31: SD_B0_01 | D31: 3.13 | F31: CLK | G31: 5 | H31: SDA1 | J31: CS2 | M31: 1B0 | N31: 44 | O31: __________| | P31: |___________ | Q31: 3.3V
O33: Back Memory Chips
B34: F2A_D0 | C34: EMC_26 | D34: 4.26 | F34: 0.05 | K34: RX1 | M34: 1B1 | N34: 52 | Q34: GND
B35: F2A_SCLK | C35: EMC_25 | D35: 4.25 | K35: TX1 | M35: 1A1 | N35: 53 | Q35: 50 | R35: 1B2 | T35: CTS8 | U35: MOSI2 | Y35: 0.051388889 | AA35: 4.28 | AB35: EMC_28 | AC35: F2A_D2
B36: F2A_D3 | C36: EMC_29 | D36: 4.29 | F36: 0.052083333 | J36: MISO2 | M36: 3A0 | N36: 54 | Q36: 49 | R36: 1A2 | U36: SCK2 | Y36: 0.050694444 | AA36: 4.27 | AB36: EMC_27 | AC36: F2A_D1
L37: 3.3V | P37: (pin 1) | Q37: 51 | R37: 3B3,Q23 | W37: SCL1 | AA37: 4.22 | AB37: EMC_22 | AC37: F2A_SS1_B
B39: F2A_D0 | C39: EMC_26 | D39: 4.26 | F39: 0.05 | K39: RX1 | M39: 1B1 | N39: 52 | Q39: GND
B40: F2A_SCLK | C40: EMC_25 | D40: 4.25 | K40: TX1 | M40: 1A1 | N40: 53 | Q40: 50 | R40: 1B2 | T40: CTS8 | U40: MOSI2 | Y40: 0.051388889 | AA40: 4.28 | AB40: EMC_28 | AC40: F2A_D2
B41: F2A_D3 | C41: EMC_29 | D41: 4.29 | F41: 0.052083333 | J41: MISO2 | M41: 3A0 | N41: 54 | Q41: 49 | R41: 1A2 | U41: SCK2 | Y41: 0.050694444 | AA41: 4.27 | AB41: EMC_27 | AC41: F2A_D1
L42: 3.3V | P42: (pin 1) | Q42: 48 | R42: 1B0 | T42: RX8 | AA42: 4.24 | AB42: EMC_24 | AC42: F2A_SSO_B

Sheet Micromod
A1: Pin | B1: MM Pin | C1: MM Func | D1: Name | E1: GPIO | F1: Serial | G1: I2C | H1: SPI | I1: PWM | J1: CAN | K1: Audio | L1: XBAR | M1: FlexIO | N1: Analog | O1: SD/CSI/LCD
A2: 00 | B2: 19 | C2: * | D2: AD_B0_03 | E2: 1.3 | F2: Serial1(6) RX | H2: SPI1(3) CS0 | I2: PWM1_X1 | J2: 2_RX | L2: IO-17
A3: 01 | B3: 17 | C3: * | D3: AD_B0_02 | E3: 1.2 | F3: Serial1(6) TX | H3: SPI1(3) MISO | I3: PWM1_X0 | J3: 2_TX | L3: IO-16
A4: 02 | B4: 47 | C4: * | D4: EMC_04 | E4: 4.4 | I4: PWM4_A2 | K4: 2:TX_DATA | L4: IO-06 | M4: 1:4
A5: 03 | B5: 32 | C5: * | D5: EMC_05 | E5: 4.5 | I5: PWM4_B2 | K5: 2:TX_SYNC | L5: IO-07 | M5: 1:5
A6: 04 | B6: 10 | C6: * | D6: EMC_06 | E6: 4.6 | I6: PWM2_A0 | K6: 2:TX_BCLK | L6: IO-08 | M6: 1:6
A7: 05 | B7: 18 | C7: * | D7: EMC_08 | E7: 4.8 | I7: PWM2_A1 | K7: 2:RX_DATA | L7: IO-17 | M7: 1:8
A8: 06 | B8: 71 | C8: * | D8: B0_10 | E8: 2.10 | I8: PWM2_A2, QT4_1 | K8: 1:TX3_RX1 | M8: 2:10 | O8: LCD_DATA6
A9: 07 | B9: 56 | D9: B1_01 | E9: 2.17 | F9: Serial4(4) RX | I9: PWM1_B3 | K9: 1:TX_DATA | L9: IO-15 | M9: 2:17, 3:17
A10: 08 | B10: 54 | D10: B1_00 | E10: 2.16 | F10: Serial4(4) TX | I10: PWM1_A3 | K10: 1:RX_DATA | L10: IO-14 | M10: 2:16, 3:16
A11: 09 | B11: 69 | C11: * | D11: B0_11 | E11: 2.11 | I11: PWM2_B2,QT4_2 | K11: 1:TX2_RX2 | M11: 2:11 | O11: LCD_DATA7
A12: 10 | B12: 55 | C12: FNCS0 | D12: B0_00 | E12: 2.0 | H12: SPI(4) CS0 | I12: QT1_0 | K12: MQS_RIGHT | M12: 2:0 | O12: LCD_CLK
A13: 11 | B13: 59 | C13: * | D13: B0_02 | E13: 2.2 | H13: SPI(4) MOSI | I13: QT1_2 | J13: 1_TX | M13: 2:2 | O13: LCD_HSYNC
A14: 12 | B14: 61 | C14: * | D14: B0_01 | E14: 2.1 | H14: SPI(4) MISO | I14: QT1_1 | K14: MQS_LEFT | M14: 2:1 | O14: LCD_ENABLE
A15: 13 | B15: 57 | C15: * | D15: B0_03 | E15: 2.3 | H15: SPI(4) SCK | I15: QT2_0 | J15: 1_RX | M15: 2:3 | O15: LCD_VSYNC
A16: 14/A0 | B16: 34 | C16: * | D16: AD_B1_02 | E16: 1.18 | F16: Serial3(2) TX | I16: QT3_2 | K16: SPDIF_OUT | M16: 3:2 | N16: A1:7, A2:7
A17: 15/A1 | B17: 38 | C17: * | D17: AD_B1_03 | E17: 1.19 | F17: Serial3(2) RX | I17: QT3_3 | K17: SPDIF_IN | M17: 3:3 | N17: A1:8, A2:8
A18: 16/A2 | B18: 20 | C18: * | D18: AD_B1_07 | E18: 1.23 | F18: Serial2(3) RX | G18: Wire2(3) SCL | K18: SPDIF_EXTCLK | M18: 3:7 | N18: A1:12, A2:12 | O18: USDHC2_DATA3
A19: 17/A3 | B19: 22 | C19: * | D19: AD_B1_06 | E19: 1.22 | F19: Serial2(3) TX | G19: Wire2(3) SDA | K19: SPDIF_LOCK | M19: 3:6 | N19: A1:11, A2:11 | O19: USDHC2_DATA2
A20: 18/A4 | B20: 12 | C20: * | D20: AD_B1_01 | E20: 1.17 | F20: Serial3(2) RTS | G20: Wire(1) SDA | I20: QT3_1 | M20: 3:1 | N20: A1:6, A2:6
A21: 19/A5 | B21: 14 | C21: * | D21: AD_B1_00 | E21: 1.16 | F21: Serial3(2) CTS | G21: Wire(1) SCL | I21: QT3_0 | M21: 3:0 | N21: A1:5, A2:5
A22: 20/A6 | B22: 52 | D22: AD_B1_10 | E22: 1.26 | F22: Serial5(8) TX | K22: 1:RX_SYNC | M22: 3:10 | N22: A1:15, A2:15
A23: 21/A7 | B23: 50 | D23: AD_B1_11 | E23: 1.27 | F23: Serial5(8) RX | K23: 1:RX_BCLK | M23: 3:11 | N23: A1:0, A2:0
A24: 22/A8 | B24: 49 | C24: * | D24: AD_B1_08 | E24: 1.24 | I24: PWM4_A0 | J24: 1_TX | M24: 3:8 | N24: A1:13, A2:13 | O24: USDHC2_CMD
A25: 23/A9 | B25: 58 | D25: AD_B1_09 | E25: 1.25 | I25: PWM4_A1 | J25: 1_RX | K25: 1:MCLK | M25: 3:9 | N25: A1:14, A2:14 | O25: USDHC2_CLK
A26: 24/A10 | B26: 53 | D26: AD_B0_12 | E26: 1.12 | F26: Serial6(1) TX | G26: Wire1(4) SCL | I26: PWM1_X2 | N26: A1:1
A27: 25/A11 | B27: 51 | D27: AD_B0_13 | E27: 1.13 | F27: Serial6(1) RX | G27: Wire1(4) SDA | I27: PWM1_X3 | J27: GPT1_CLK | N27: A1:2
A28: 26/A12 | B28: 67 | D28: AD_B1_14 | E28: 1.30 | H28: SPI1(3) MOSI | K28: 1:TX_BCLK | M28: 3:14 | N28: A2:3
A29: 27/A13 | B29: 8 | D29: AD_B1_15 | E29: 1.31 | H29: SPI1(3) SCK | K29: 1:TX_SYNC | M29: 3:15 | N29: A2:4
A30: 28 | B30: 4 | D30: EMC_32 | E30: 3.18 | F30: Serial7(7) RX | I30: PWM3_B1
A31: 29 | B31: 16 | C31: * | D31: EMC_31 | E31: 4.31 | F31: Serial7(7) TX | H31: SPI2(1) CS1 | I31: PWM3_A1
A32: 30 | B32: 41 | C32: *0 | D32: EMC_37 | E32: 3.23 | I32: GPT1_3 | J32: 3_RX | K32: 3:MCLK | L32: IO-23
A33: 31 | B33: 43 | C33: *0 | D33: EMC_36 | E33: 3.22 | I33: GPT1_2 | J33: 3_TX | K33: 3:TX_DATA | L33: IO-22
A34: 32 | B34: 65 | D34: B0_12 | E34: 2.12 | K34: 1:TX1_RX3 | L34: IO-10 | M34: 2:12 | O34: LCD_DATA8
A35: 33 | B35: 63 | D35: EMC_07 | E35: 4.7 | I35: PWM2_B0 | K35: 2:MCLK | L35: IO-09 | M35: 1:7
A36: 34 | B36: 66 | C36: FPE1 | D36: SD_B0_03 | E36: 3.15 | F36: Serial5(8) RTS | H36: SPI2(1) MISO | I36: PWM1_B1 | L36: IO-07 | O36: DATA1
A37: 35 | B37: 64 | D37: SD_B0_02 | E37: 3.14 | F37: Serial5(8) CTS | H37: SPI2(1) MOSI | I37: PWM1_A1 | L37: IO-06 | O37: DATA0
A38: 36 | B38: 60 | C38: * | D38: SD_B0_01 | E38: 3.13 | G38: Wire2(3) SDA | H38: SPI2(1) CS0 | I38: PWM1_B0 | L38: IO-05 | O38: CLK
A39: 37 | B39: 62 | C39: * | D39: SD_B0_00 | E39: 3.12 | G39: Wire2(3) SCL | H39: SPI2(1) SCK | I39: PWM1_A0 | L39: IO-04 | O39: CMD
A40: 38 | B40: 68 | C40: FPE0 | D40: SD_B0_04 | E40: 3.16 | F40: Serial5(8) TX | H40: FLEXSPI B_SSO_B | I40: PWM1_A2 | L40: IO-08 | O40: DATA2
...

Sheet MMod OV757x
A1: Pin | B1: MM Pin | C1: OV767X Shield | D1: MM ATP | E1: MM Func | F1: Name | G1: GPIO | H1: Serial | I1: I2C | J1: SPI | K1: PWM | L1: CAN | M1: Audio | N1: XBAR | O1: FlexIO | P1: Analog | Q1: SD/CSI/LCD
A2: 00 | B2: 19 | D2: UART_TX1 | E2: * | F2: AD_B0_03 | G2: 1.3 | H2: Serial1(6) RX | J2: SPI1(3) CS0 | K2: PWM1_X1 | L2: 2_RX | N2: IO-17
A3: 01 | B3: 17 | D3: UART_RX1 | E3: * | F3: AD_B0_02 | G3: 1.2 | H3: Serial1(6) TX | J3: SPI1(3) MISO | K3: PWM1_X0 | L3: 2_TX | N3: IO-16
A4: 02 | B4: 47 | C4: TFT_RST | D4: PWM1 | E4: * | F4: EMC_04 | G4: 4.4 | K4: PWM4_A2 | M4: 2:TX_DATA | N4: IO-06 | O4: 1:4
A5: 03 | B5: 32 | C5: TFT_BACKLIGHT | D5: PWM0 | E5: * | F5: EMC_05 | G5: 4.5 | K5: PWM4_B2 | M5: 2:TX_SYNC | N5: IO-07 | O5: 1:5
A6: 04 | B6: 10 | C6: TFT_DC | D6: D0 | E6: * | F6: EMC_06 | G6: 4.6 | K6: PWM2_A0 | M6: 2:TX_BCLK | N6: IO-08 | O6: 1:6
A7: 05 | B7: 18 | C7: TFT_CS | D7: D1 | E7: * | F7: EMC_08 | G7: 4.8 | K7: PWM2_A1 | M7: 2:RX_DATA | N7: IO-17 | O7: 1:8
A8: 06 | B8: 71 | C8: CAMERA_D6 | D8: G6/BUS6 | E8: * | F8: B0_10 | G8: 2.10 | K8: PWM2_A2, QT4_1 | M8: 1:TX3_RX1 | O8: 2:10 | Q8: LCD_DATA6
A9: 07 | B9: 56 | C9: AUDIO | D9: AUD_OUT | F9: B1_01 | G9: 2.17 | H9: Serial4(4) RX | K9: PWM1_B3 | M9: 1:TX_DATA | N9: IO-15 | O9: 2:17, 3:17
A10: 08 | B10: 54 | C10: AUDIO | D10: AUD_IN | F10: B1_00 | G10: 2.16 | H10: Serial4(4) TX | K10: PWM1_A3 | M10: 1:RX_DATA | N10: IO-14 | O10: 2:16, 3:16
A11: 09 | B11: 69 | C11: CAMERA_D7 | D11: G7/BUS7 | E11: * | F11: B0_11 | G11: 2.11 | K11: PWM2_B2,QT4_2 | M11: 1:TX2_RX2 | O11: 2:11 | Q11: LCD_DATA7
A12: 10 | B12: 55 | C12: CAMERA_PCLK | D12: SPI_CS | E12: FNCS0 | F12: B0_00 | G12: 2.0 | J12: SPI(4) CS0 | K12: QT1_0 | M12: MQS_RIGHT | O12: 2:0 | Q12: LCD_CLK
A13: 11 | B13: 59 | C13: SPI_MOSI | D13: SPI_SCOPI | E13: * | F13: B0_02 | G13: 2.2 | J13: SPI(4) MOSI | K13: QT1_2 | L13: 1_TX | O13: 2:2 | Q13: LCD_HSYNC
A14: 12 | B14: 61 | C14: SPI_MISO | D14: SPI_CIPO | E14: * | F14: B0_01 | G14: 2.1 | J14: SPI(4) MISO | K14: QT1_1 | M14: MQS_LEFT | O14: 2:1 | Q14: LCD_ENABLE
A15: 13 | B15: 57 | C15: SPI_CLK | D15: SPI_SCK | E15: * | F15: B0_03 | G15: 2.3 | J15: SPI(4) SCK | K15: QT2_0 | L15: 1_RX | O15: 2:3 | Q15: LCD_VSYNC
A16: 14/A0 | B16: 34 | D16: A0 | E16: * | F16: AD_B1_02 | G16: 1.18 | H16: Serial3(2) TX | K16: QT3_2 | M16: SPDIF_OUT | O16: 3:2 | P16: A1:7, A2:7
A17: 15/A1 | B17: 38 | C17: TFT_ADA_CS_SD | D17: A1 | E17: * | F17: AD_B1_03 | G17: 1.19 | H17: Serial3(2) RX | K17: QT3_3 | M17: SPDIF_IN | O17: 3:3 | P17: A1:8, A2:8
A18: 16/A2 | B18: 20 | D18: UART_RX2 | E18: * | F18: AD_B1_07 | G18: 1.23 | H18: Serial2(3) RX | I18: Wire2(3) SCL | M18: SPDIF_EXTCLK | O18: 3:7 | P18: A1:12, A2:12 | Q18: USDHC2_DATA3
A19: 17/A3 | B19: 22 | D19: UART_TX2 | E19: * | F19: AD_B1_06 | G19: 1.22 | H19: Serial2(3) TX | I19: Wire2(3) SDA | M19: SPDIF_LOCK | O19: 3:6 | P19: A1:11, A2:11 | Q19: USDHC2_DATA2
A20: 18/A4 | B20: 12 | C20: WIRE(CAM/AUD) | D20: I2C_SDA | E20: * | F20: AD_B1_01 | G20: 1.17 | H20: Serial3(2) RTS | I20: Wire(1) SDA | K20: QT3_1 | O20: 3:1 | P20: A1:6, A2:6
A21: 19/A5 | B21: 14 | C21: WIRE(CAM/AUD) | D21: I2C_SCL | E21: * | F21: AD_B1_00 | G21: 1.16 | H21: Serial3(2) CTS | I21: Wire(1) SCL | K21: QT3_0 | O21: 3:0 | P21: A1:5, A2:5
A22: 20/A6 | B22: 52 | C22: AUDIO | D22: AUD_LRCLK | F22: AD_B1_10 | G22: 1.26 | H22: Serial5(8) TX | M22: 1:RX_SYNC | O22: 3:10 | P22: A1:15, A2:15
A23: 21/A7 | B23: 50 | C23: AUDIO | D23: AUD_BCLK | F23: AD_B1_11 | G23: 1.27 | H23: Serial5(8) RX | M23: 1:RX_BCLK | O23: 3:11 | P23: A1:0, A2:0
A24: 22/A8 | B24: 49 | C24: <NO EDGE PIN> | D24: BATT_VIN3 | E24: * | F24: AD_B1_08 | G24: 1.24 | K24: PWM4_A0 | L24: 1_TX | O24: 3:8 | P24: A1:13, A2:13 | Q24: USDHC2_CMD
A25: 23/A9 | B25: 58 | C25: AUDIO | D25: AUD_MCLK | F25: AD_B1_09 | G25: 1.25 | K25: PWM4_A1 | L25: 1_RX | M25: 1:MCLK | O25: 3:9 | P25: A1:14, A2:14 | Q25: USDHC2_CLK
A26: 24/A10 | B26: 53 | D26: I2C_SCL1 | F26: AD_B0_12 | G26: 1.12 | H26: Serial6(1) TX | I26: Wire1(4) SCL | K26: PWM1_X2 | P26: A1:1
